Workbook

Sheet README
A1: PITCHBOOK DATA REQUEST · 11 Franchisors · For Accel-KKR
A2: Velocity GTM Co · Prepared for GPSI/ServiceBridge · April 21, 2026
A4: PURPOSE
A5: This spreadsheet captures the specific data points Velocity GTM needs to build the PE narrative and franchisor pitch for each of our 11 Track 1 targets. It exists as a backup in case direct PitchBook access isn't granted — Accel-KKR can fill in the gaps directly. One tab per franchisor (11 total). Each tab uses the same structure so data fills consistently. Green-shaded cells are pre-populated with what we already know from public sources. White cells are gaps we need Accel-KKR to fill.
A7: HOW TO FILL
A8: Priority column indicates what matters most: P1 (red) = MUST-HAVE. Core to the PE narrative letter or Insight Engine ROI calculation. P2 (amber) = SHOULD-HAVE. Strengthens the franchisor-specific pitch. P3 (grey) = NICE-TO-HAVE. Context or supporting detail. If a data point is unknown or unavailable, enter "NOT AVAILABLE" so we can distinguish gaps from blanks. If a data point has a range, enter the range (e.g., "$15M–$20M"). Source citations are welcomed but not required — if you paste from PitchBook, we'll trust the data.
A10: USE CASES
A11: The data feeds three deliverables: 1. PE narrative letters to each franchisor's PE backer — ownership, hold period, fund dynamics 2. Franchisor-specific pitch decks — unit economics, growth trajectory, FSM landscape 3. Insight Engine ROI model — tech counts, revenue, EBITDA, exit multiples for value-creation math
A13: TIMING
A14: Ideally filled by end of April 2026. Data informs the Week 3–4 deliverables (PE narrative letters + franchisor pitch materials) in the ServiceBridge GTM plan.
A16: TAB INDEX
A17: Priority 1 (Active Focus) | B17: Neighborly, Authority, Empower, PSB, HomeFront, Five Star, ResiBrands
A18: Priority 2 (Existing Footprint) | B18: Evive, Threshold, BELFOR
A19: Priority 3 (Strategic Account) | B19: Rollins (public company)

Sheet Data Priority Legend
A1: DATA PRIORITY LEGEND · What we need and why
A3: CATEGORY | B3: DATA POINT | C3: PRIORITY | D3: WHY IT MATTERS | E3: USE CASE
A4: A. Company Overview | B4: Legal entity / parent structure | C4: P1 | D4: Clarifies who actually signs a mandate — franchisor vs. parent vs. portco. | E4: PE letter + pitch
A5: A. Company Overview | B5: HQ location | C5: P3 | D5: Context for meeting logistics, regional alignment. | E5: Pitch context
A6: A. Company Overview | B6: Year founded / acquired | C6: P2 | D6: Maturity signal. Recent platform = still shaping, longer runway. | E6: PE letter
A7: A. Company Overview | B7: Number of brands in portfolio | C7: P1 | D7: Confirms/validates our current count. Drives Insight Engine territory math. | E7: Insight Engine
A8: A. Company Overview | B8: Number of franchisees (total units) | C8: P1 | D8: Most-critical metric. Drives addressable market and ROI model. | E8: Insight Engine
A9: B. Ownership | B9: Current majority owner | C9: P1 | D9: Confirms PE firm (critical for warm-intro path identification). | E9: PE letter
A10: B. Ownership | B10: Minority investors / co-investors | C10: P2 | D10: Board dynamics. BCI + Apax co-invest at Authority is a known pattern. | E10: PE letter
A11: B. Ownership | B11: Acquisition date / initial investment | C11: P1 | D11: Establishes hold period — Year 3–5 is our prime window for mandate conversations. | E11: PE letter timing
A12: B. Ownership | B12: Fund vintage / fund size | C12: P2 | D12: Fund dynamics — end-of-life funds push for exits; vintage funds push for growth. | E12: PE letter framing
A13: B. Ownership | B13: Anticipated exit window | C13: P2 | D13: If PE is 1–2 years from exit, the mandate conversation is time-sensitive. | E13: Timing urgency
A14: B. Ownership | B14: Prior ownership history | C14: P3 | D14: Narrative color — turnaround story, roll-up, spin-off, etc. | E14: Pitch color
... A40: G. Narrative | B40: Awards / industry rankings | C40: P3 | D40: Credibility framing for the pitch letter. | E40: Pitch color

Sheet 01 Neighborly
A1: Neighborly · Priority 1 · Active Focus | E1: P1
A2: Green cells = pre-populated (known) · White cells = need Accel-KKR to fill · If unknown, enter "NOT AVAILABLE"
A4: CATEGORY | B4: DATA POINT | C4: PRIORITY | D4: VALUE / DATA | E4: SOURCE / NOTES
A5: A. Company Overview
B6: Legal entity / parent structure | C6: P1 | D6: Neighborly (parent), Dwyer Group legacy
B7: HQ location | C7: P3 | D7: Waco, Texas
B8: Year founded / acquired | C8: P2 | D8: 1980s origins; KKR acquired 2021
B9: Number of brands in portfolio | C9: P1 | D9: 25+
B10: Number of franchisees (total units) | C10: P1 | D10: 5,500+ franchises
A11: B. Ownership & PE Structure
B12: Current majority owner | C12: P1 | D12: KKR ($349B+ AUM)
B13: Minority investors / co-investors | C13: P2
B14: Acquisition date / initial investment | C14: P1 | D14: 2021
B15: Fund vintage / fund size | C15: P2
B16: Anticipated exit window | C16: P2
B17: Prior ownership history | C17: P3
A18: C. Financial Performance
B19: Systemwide sales ($) | C19: P1
B20: Royalty + marketing fund revenue | C20: P1
B21: EBITDA (last 12 months) | C21: P1
B22: EBITDA margin % | C22: P2
B23: Revenue growth rate (YoY) | C23: P2
B24: Most recent valuation / enterprise value | C24: P2
A25: D. Franchisee Unit Economics
B26: Average unit AUV | C26: P1
B27: Average unit EBITDA | C27: P1
B28: Average franchisee tenure | C28: P2
B29: Multi-unit ownership % | C29: P2
B30: Average franchise fee / initial investment | C30: P3
A31: E. Growth & Territory Data
B32: Number of units added (last 3 years) | C32: P1
B33: Number of units closed (last 3 years) | C33: P2
B34: Planned unit openings (next 2 years) | C34: P2
B35: Geographic concentration (top 5 states) | C35: P3
B36: International footprint | C36: P3
A37: F. Technology Stack
B38: Current FSM platform(s) used across network | C38: P1 | D38: Mix — ServiceTitan partial, franchisee choice for others
B39: CRM platform used | C39: P2
B40: Telematics / fleet tracking provider | C40: P1 | D40: Smart Fleet USA / Azuga (CONFIRMED — hard GPSI conflict)
B41: Payment processing / financing provider | C41: P2
...

Sheet 02 Authority Brands
A1: Authority Brands · Priority 1 · Active Focus | E1: P1
A2: Green cells = pre-populated (known) · White cells = need Accel-KKR to fill · If unknown, enter "NOT AVAILABLE"
A4: CATEGORY | B4: DATA POINT | C4: PRIORITY | D4: VALUE / DATA | E4: SOURCE / NOTES
A5: A. Company Overview
B6: Legal entity / parent structure | C6: P1 | D6: Authority Brands, Inc.
B7: HQ location | C7: P3 | D7: Columbia, Maryland
B8: Year founded / acquired | C8: P2 | D8: 2018 (platform formation)
B9: Number of brands in portfolio | C9: P1 | D9: 14
B10: Number of franchisees (total units) | C10: P1 | D10: 1,700+ units
A11: B. Ownership & PE Structure
B12: Current majority owner | C12: P1 | D12: Apax Partners
B13: Minority investors / co-investors | C13: P2 | D13: British Columbia Investment Management Corporation (BCI)
B14: Acquisition date / initial investment | C14: P1 | D14: 2021 (Apax acquired from Thoma Bravo)
B15: Fund vintage / fund size | C15: P2
B16: Anticipated exit window | C16: P2
B17: Prior ownership history | C17: P3
A18: C. Financial Performance
B19: Systemwide sales ($) | C19: P1
B20: Royalty + marketing fund revenue | C20: P1
B21: EBITDA (last 12 months) | C21: P1
B22: EBITDA margin % | C22: P2
B23: Revenue growth rate (YoY) | C23: P2
B24: Most recent valuation / enterprise value | C24: P2
A25: D. Franchisee Unit Economics
B26: Average unit AUV | C26: P1
B27: Average unit EBITDA | C27: P1
B28: Average franchisee tenure | C28: P2
B29: Multi-unit ownership % | C29: P2
B30: Average franchise fee / initial investment | C30: P3
A31: E. Growth & Territory Data
B32: Number of units added (last 3 years) | C32: P1
B33: Number of units closed (last 3 years) | C33: P2
B34: Planned unit openings (next 2 years) | C34: P2
B35: Geographic concentration (top 5 states) | C35: P3
B36: International footprint | C36: P3
A37: F. Technology Stack
B38: Current FSM platform(s) used across network | C38: P1 | D38: ServiceTitan (active partnership announced 2024)
B39: CRM platform used | C39: P2
B40: Telematics / fleet tracking provider | C40: P1
B41: Payment processing / financing provider | C41: P2
...

Sheet 03 Empower Brands
A1: Empower Brands · Priority 1 · Active Focus | E1: P1
A2: Green cells = pre-populated (known) · White cells = need Accel-KKR to fill · If unknown, enter "NOT AVAILABLE"
A4: CATEGORY | B4: DATA POINT | C4: PRIORITY | D4: VALUE / DATA | E4: SOURCE / NOTES
A5: A. Company Overview
B6: Legal entity / parent structure | C6: P1 | D6: Empower Brands
B7: HQ location | C7: P3 | D7: Virginia Beach, Virginia
B8: Year founded / acquired | C8: P2
B9: Number of brands in portfolio | C9: P1 | D9: 16
B10: Number of franchisees (total units) | C10: P1 | D10: ~11,755 units (incl. JAN-PRO 10,000)
A11: B. Ownership & PE Structure
B12: Current majority owner | C12: P1 | D12: MidOcean Partners
B13: Minority investors / co-investors | C13: P2
B14: Acquisition date / initial investment | C14: P1 | D14: 2022
B15: Fund vintage / fund size | C15: P2
B16: Anticipated exit window | C16: P2
B17: Prior ownership history | C17: P3
A18: C. Financial Performance
B19: Systemwide sales ($) | C19: P1
B20: Royalty + marketing fund revenue | C20: P1
B21: EBITDA (last 12 months) | C21: P1
B22: EBITDA margin % | C22: P2
B23: Revenue growth rate (YoY) | C23: P2
B24: Most recent valuation / enterprise value | C24: P2
A25: D. Franchisee Unit Economics
B26: Average unit AUV | C26: P1
B27: Average unit EBITDA | C27: P1
B28: Average franchisee tenure | C28: P2
B29: Multi-unit ownership % | C29: P2
B30: Average franchise fee / initial investment | C30: P3
A31: E. Growth & Territory Data
B32: Number of units added (last 3 years) | C32: P1
B33: Number of units closed (last 3 years) | C33: P2
B34: Planned unit openings (next 2 years) | C34: P2
B35: Geographic concentration (top 5 states) | C35: P3
B36: International footprint | C36: P3
A37: F. Technology Stack
B38: Current FSM platform(s) used across network | C38: P1
B39: CRM platform used | C39: P2
B40: Telematics / fleet tracking provider | C40: P1
B41: Payment processing / financing provider | C41: P2
...

Sheet 04 Premium Service Brands
A1: Premium Service Brands · Priority 1 · Active Focus | E1: P1
A2: Green cells = pre-populated (known) · White cells = need Accel-KKR to fill · If unknown, enter "NOT AVAILABLE"
A4: CATEGORY | B4: DATA POINT | C4: PRIORITY | D4: VALUE / DATA | E4: SOURCE / NOTES
A5: A. Company Overview
B6: Legal entity / parent structure | C6: P1 | D6: Premium Service Brands
B7: HQ location | C7: P3 | D7: Charlottesville, Virginia
B8: Year founded / acquired | C8: P2
B9: Number of brands in portfolio | C9: P1 | D9: 9
B10: Number of franchisees (total units) | C10: P1 | D10: ~595 units
A11: B. Ownership & PE Structure
B12: Current majority owner | C12: P1 | D12: Susquehanna Private Capital (needs verification — RiverGlade also cited)
B13: Minority investors / co-investors | C13: P2
B14: Acquisition date / initial investment | C14: P1
B15: Fund vintage / fund size | C15: P2
B16: Anticipated exit window | C16: P2
B17: Prior ownership history | C17: P3
A18: C. Financial Performance
B19: Systemwide sales ($) | C19: P1
B20: Royalty + marketing fund revenue | C20: P1
B21: EBITDA (last 12 months) | C21: P1
B22: EBITDA margin % | C22: P2
B23: Revenue growth rate (YoY) | C23: P2
B24: Most recent valuation / enterprise value | C24: P2
A25: D. Franchisee Unit Economics
B26: Average unit AUV | C26: P1
B27: Average unit EBITDA | C27: P1
B28: Average franchisee tenure | C28: P2
B29: Multi-unit ownership % | C29: P2
B30: Average franchise fee / initial investment | C30: P3
A31: E. Growth & Territory Data
B32: Number of units added (last 3 years) | C32: P1
B33: Number of units closed (last 3 years) | C33: P2
B34: Planned unit openings (next 2 years) | C34: P2
B35: Geographic concentration (top 5 states) | C35: P3
B36: International footprint | C36: P3
A37: F. Technology Stack
B38: Current FSM platform(s) used across network | C38: P1
B39: CRM platform used | C39: P2
B40: Telematics / fleet tracking provider | C40: P1
B41: Payment processing / financing provider | C41: P2
...

Sheet 05 HomeFront Brands
A1: HomeFront Brands · Priority 1 · Active Focus | E1: P1
A2: Green cells = pre-populated (known) · White cells = need Accel-KKR to fill · If unknown, enter "NOT AVAILABLE"
A4: CATEGORY | B4: DATA POINT | C4: PRIORITY | D4: VALUE / DATA | E4: SOURCE / NOTES
A5: A. Company Overview
B6: Legal entity / parent structure | C6: P1 | D6: HomeFront Brands
B7: HQ location | C7: P3 | D7: Charlotte, North Carolina
B8: Year founded / acquired | C8: P2 | D8: 2022 (platform)
B9: Number of brands in portfolio | C9: P1 | D9: 6
B10: Number of franchisees (total units) | C10: P1 | D10: ~185 units
A11: B. Ownership & PE Structure
B12: Current majority owner | C12: P1 | D12: Dudan Group (family office) / Trilantic Capital Partners (structure to verify)
B13: Minority investors / co-investors | C13: P2
B14: Acquisition date / initial investment | C14: P1
B15: Fund vintage / fund size | C15: P2
B16: Anticipated exit window | C16: P2
B17: Prior ownership history | C17: P3
A18: C. Financial Performance
B19: Systemwide sales ($) | C19: P1
B20: Royalty + marketing fund revenue | C20: P1
B21: EBITDA (last 12 months) | C21: P1
B22: EBITDA margin % | C22: P2
B23: Revenue growth rate (YoY) | C23: P2
B24: Most recent valuation / enterprise value | C24: P2
A25: D. Franchisee Unit Economics
B26: Average unit AUV | C26: P1
B27: Average unit EBITDA | C27: P1
B28: Average franchisee tenure | C28: P2
B29: Multi-unit ownership % | C29: P2
B30: Average franchise fee / initial investment | C30: P3
A31: E. Growth & Territory Data
B32: Number of units added (last 3 years) | C32: P1
B33: Number of units closed (last 3 years) | C33: P2
B34: Planned unit openings (next 2 years) | C34: P2
B35: Geographic concentration (top 5 states) | C35: P3
B36: International footprint | C36: P3
A37: F. Technology Stack
B38: Current FSM platform(s) used across network | C38: P1
B39: CRM platform used | C39: P2
B40: Telematics / fleet tracking provider | C40: P1
B41: Payment processing / financing provider | C41: P2
...

Sheet 06 Five Star Franchising
A1: Five Star Franchising · Priority 1 · Active Focus | E1: P1
A2: Green cells = pre-populated (known) · White cells = need Accel-KKR to fill · If unknown, enter "NOT AVAILABLE"
A4: CATEGORY | B4: DATA POINT | C4: PRIORITY | D4: VALUE / DATA | E4: SOURCE / NOTES
A5: A. Company Overview
B6: Legal entity / parent structure | C6: P1 | D6: Five Star Franchising
B7: HQ location | C7: P3 | D7: Orem, Utah
B8: Year founded / acquired | C8: P2
B9: Number of brands in portfolio | C9: P1 | D9: 4 (may include Gotcha Covered — needs verification)
B10: Number of franchisees (total units) | C10: P1 | D10: ~580 units
A11: B. Ownership & PE Structure
B12: Current majority owner | C12: P1 | D12: Princeton Equity Group (franchise-focused PE); conflicting sources cite MPK Equity and Trive Capital — needs confirmation
B13: Minority investors / co-investors | C13: P2
B14: Acquisition date / initial investment | C14: P1
B15: Fund vintage / fund size | C15: P2
B16: Anticipated exit window | C16: P2
B17: Prior ownership history | C17: P3
A18: C. Financial Performance
B19: Systemwide sales ($) | C19: P1
B20: Royalty + marketing fund revenue | C20: P1
B21: EBITDA (last 12 months) | C21: P1
B22: EBITDA margin % | C22: P2
B23: Revenue growth rate (YoY) | C23: P2
B24: Most recent valuation / enterprise value | C24: P2
A25: D. Franchisee Unit Economics
B26: Average unit AUV | C26: P1
B27: Average unit EBITDA | C27: P1
B28: Average franchisee tenure | C28: P2
B29: Multi-unit ownership % | C29: P2
B30: Average franchise fee / initial investment | C30: P3
A31: E. Growth & Territory Data
B32: Number of units added (last 3 years) | C32: P1
B33: Number of units closed (last 3 years) | C33: P2
B34: Planned unit openings (next 2 years) | C34: P2
B35: Geographic concentration (top 5 states) | C35: P3
B36: International footprint | C36: P3
A37: F. Technology Stack
B38: Current FSM platform(s) used across network | C38: P1
B39: CRM platform used | C39: P2
B40: Telematics / fleet tracking provider | C40: P1
B41: Payment processing / financing provider | C41: P2
...

Sheet 07 ResiBrands
A1: ResiBrands · Priority 1 · Active Focus | E1: P1
A2: Green cells = pre-populated (known) · White cells = need Accel-KKR to fill · If unknown, enter "NOT AVAILABLE"
A4: CATEGORY | B4: DATA POINT | C4: PRIORITY | D4: VALUE / DATA | E4: SOURCE / NOTES
A5: A. Company Overview
B6: Legal entity / parent structure | C6: P1 | D6: ResiBrands
B7: HQ location | C7: P3 | D7: Austin, Texas
B8: Year founded / acquired | C8: P2
B9: Number of brands in portfolio | C9: P1 | D9: 5
B10: Number of franchisees (total units) | C10: P1 | D10: ~230 units
A11: B. Ownership & PE Structure
B12: Current majority owner | C12: P1 | D12: Founder-led / Trivest Partners / Codie Sanchez angel (structure to verify)
B13: Minority investors / co-investors | C13: P2
B14: Acquisition date / initial investment | C14: P1
B15: Fund vintage / fund size | C15: P2
B16: Anticipated exit window | C16: P2
B17: Prior ownership history | C17: P3
A18: C. Financial Performance
B19: Systemwide sales ($) | C19: P1
B20: Royalty + marketing fund revenue | C20: P1
B21: EBITDA (last 12 months) | C21: P1
B22: EBITDA margin % | C22: P2
B23: Revenue growth rate (YoY) | C23: P2
B24: Most recent valuation / enterprise value | C24: P2
A25: D. Franchisee Unit Economics
B26: Average unit AUV | C26: P1
B27: Average unit EBITDA | C27: P1
B28: Average franchisee tenure | C28: P2
B29: Multi-unit ownership % | C29: P2
B30: Average franchise fee / initial investment | C30: P3
A31: E. Growth & Territory Data
B32: Number of units added (last 3 years) | C32: P1
B33: Number of units closed (last 3 years) | C33: P2
B34: Planned unit openings (next 2 years) | C34: P2
B35: Geographic concentration (top 5 states) | C35: P3
B36: International footprint | C36: P3
A37: F. Technology Stack
B38: Current FSM platform(s) used across network | C38: P1
B39: CRM platform used | C39: P2
B40: Telematics / fleet tracking provider | C40: P1
B41: Payment processing / financing provider | C41: P2
...

Sheet 08 Evive Brands
A1: Evive Brands · Priority 2 · Existing Footprint | E1: P2
A2: Green cells = pre-populated (known) · White cells = need Accel-KKR to fill · If unknown, enter "NOT AVAILABLE"
A4: CATEGORY | B4: DATA POINT | C4: PRIORITY | D4: VALUE / DATA | E4: SOURCE / NOTES
A5: A. Company Overview
B6: Legal entity / parent structure | C6: P1 | D6: Evive Brands
B7: HQ location | C7: P3 | D7: Cleveland, Ohio (Riverside HQ)
B8: Year founded / acquired | C8: P2 | D8: 2023 (platform formation via Riverside roll-up)
B9: Number of brands in portfolio | C9: P1 | D9: 7
B10: Number of franchisees (total units) | C10: P1 | D10: 1,100+ territories
A11: B. Ownership & PE Structure
B12: Current majority owner | C12: P1 | D12: The Riverside Company ($13B+ AUM)
B13: Minority investors / co-investors | C13: P2
B14: Acquisition date / initial investment | C14: P1
B15: Fund vintage / fund size | C15: P2
B16: Anticipated exit window | C16: P2
B17: Prior ownership history | C17: P3
A18: C. Financial Performance
B19: Systemwide sales ($) | C19: P1
B20: Royalty + marketing fund revenue | C20: P1
B21: EBITDA (last 12 months) | C21: P1
B22: EBITDA margin % | C22: P2
B23: Revenue growth rate (YoY) | C23: P2
B24: Most recent valuation / enterprise value | C24: P2
A25: D. Franchisee Unit Economics
B26: Average unit AUV | C26: P1
B27: Average unit EBITDA | C27: P1
B28: Average franchisee tenure | C28: P2
B29: Multi-unit ownership % | C29: P2
B30: Average franchise fee / initial investment | C30: P3
A31: E. Growth & Territory Data
B32: Number of units added (last 3 years) | C32: P1
B33: Number of units closed (last 3 years) | C33: P2
B34: Planned unit openings (next 2 years) | C34: P2
B35: Geographic concentration (top 5 states) | C35: P3
B36: International footprint | C36: P3
A37: F. Technology Stack
B38: Current FSM platform(s) used across network | C38: P1 | D38: ServiceBridge (43% Brothers Gutters penetration, growing)
B39: CRM platform used | C39: P2
B40: Telematics / fleet tracking provider | C40: P1
B41: Payment processing / financing provider | C41: P2
...

Sheet 09 Threshold Brands
A1: Threshold Brands · Priority 2 · Existing Footprint | E1: P2
A2: Green cells = pre-populated (known) · White cells = need Accel-KKR to fill · If unknown, enter "NOT AVAILABLE"
A4: CATEGORY | B4: DATA POINT | C4: PRIORITY | D4: VALUE / DATA | E4: SOURCE / NOTES
A5: A. Company Overview
B6: Legal entity / parent structure | C6: P1 | D6: Threshold Brands
B7: HQ location | C7: P3 | D7: Cleveland, Ohio (Riverside HQ)
B8: Year founded / acquired | C8: P2
B9: Number of brands in portfolio | C9: P1 | D9: 10+
B10: Number of franchisees (total units) | C10: P1 | D10: ~1,000 territories
A11: B. Ownership & PE Structure
B12: Current majority owner | C12: P1 | D12: The Riverside Company ($13B+ AUM)
B13: Minority investors / co-investors | C13: P2
B14: Acquisition date / initial investment | C14: P1
B15: Fund vintage / fund size | C15: P2
B16: Anticipated exit window | C16: P2
B17: Prior ownership history | C17: P3
A18: C. Financial Performance
B19: Systemwide sales ($) | C19: P1
B20: Royalty + marketing fund revenue | C20: P1
B21: EBITDA (last 12 months) | C21: P1
B22: EBITDA margin % | C22: P2
B23: Revenue growth rate (YoY) | C23: P2
B24: Most recent valuation / enterprise value | C24: P2
A25: D. Franchisee Unit Economics
B26: Average unit AUV | C26: P1
B27: Average unit EBITDA | C27: P1
B28: Average franchisee tenure | C28: P2
B29: Multi-unit ownership % | C29: P2
B30: Average franchise fee / initial investment | C30: P3
A31: E. Growth & Territory Data
B32: Number of units added (last 3 years) | C32: P1
B33: Number of units closed (last 3 years) | C33: P2
B34: Planned unit openings (next 2 years) | C34: P2
B35: Geographic concentration (top 5 states) | C35: P3
B36: International footprint | C36: P3
A37: F. Technology Stack
B38: Current FSM platform(s) used across network | C38: P1 | D38: ServiceBridge (75% USA Insulation, at-risk over next year)
B39: CRM platform used | C39: P2
B40: Telematics / fleet tracking provider | C40: P1
B41: Payment processing / financing provider | C41: P2
...

Sheet 10 BELFOR Franchise Group
A1: BELFOR Franchise Group · Priority 2 · Existing Footprint | E1: P2
A2: Green cells = pre-populated (known) · White cells = need Accel-KKR to fill · If unknown, enter "NOT AVAILABLE"
A4: CATEGORY | B4: DATA POINT | C4: PRIORITY | D4: VALUE / DATA | E4: SOURCE / NOTES
A5: A. Company Overview
B6: Legal entity / parent structure | C6: P1 | D6: BELFOR Franchise Group (subsidiary of BELFOR Holdings)
B7: HQ location | C7: P3 | D7: Birmingham, Michigan
B8: Year founded / acquired | C8: P2 | D8: Franchise Group formed ~2010; American Securities acquired BELFOR Holdings 2019
B9: Number of brands in portfolio | C9: P1 | D9: 20+
B10: Number of franchisees (total units) | C10: P1 | D10: 9,250 technicians systemwide
A11: B. Ownership & PE Structure
B12: Current majority owner | C12: P1 | D12: American Securities (~$10B AUM)
B13: Minority investors / co-investors | C13: P2
B14: Acquisition date / initial investment | C14: P1 | D14: 2019
B15: Fund vintage / fund size | C15: P2
B16: Anticipated exit window | C16: P2
B17: Prior ownership history | C17: P3
A18: C. Financial Performance
B19: Systemwide sales ($) | C19: P1
B20: Royalty + marketing fund revenue | C20: P1
B21: EBITDA (last 12 months) | C21: P1
B22: EBITDA margin % | C22: P2
B23: Revenue growth rate (YoY) | C23: P2
B24: Most recent valuation / enterprise value | C24: P2
A25: D. Franchisee Unit Economics
B26: Average unit AUV | C26: P1
B27: Average unit EBITDA | C27: P1
B28: Average franchisee tenure | C28: P2
B29: Multi-unit ownership % | C29: P2
B30: Average franchise fee / initial investment | C30: P3
A31: E. Growth & Territory Data
B32: Number of units added (last 3 years) | C32: P1
B33: Number of units closed (last 3 years) | C33: P2
B34: Planned unit openings (next 2 years) | C34: P2
B35: Geographic concentration (top 5 states) | C35: P3
B36: International footprint | C36: P3
A37: F. Technology Stack
B38: Current FSM platform(s) used across network | C38: P1 | D38: ServiceBridge de facto standard in HOODZ/DUCTZ (94% each). No franchisor-level mandate.
B39: CRM platform used | C39: P2
B40: Telematics / fleet tracking provider | C40: P1
B41: Payment processing / financing provider | C41: P2
...

Sheet 11 Rollins Inc
A1: Rollins Inc · Priority 3 · Strategic Account | E1: P3
A2: Green cells = pre-populated (known) · White cells = need Accel-KKR to fill · If unknown, enter "NOT AVAILABLE"
A4: CATEGORY | B4: DATA POINT | C4: PRIORITY | D4: VALUE / DATA | E4: SOURCE / NOTES
A5: A. Company Overview
B6: Legal entity / parent structure | C6: P1 | D6: Rollins, Inc. (publicly traded)
B7: HQ location | C7: P3 | D7: Atlanta, Georgia
B8: Year founded / acquired | C8: P2 | D8: 1948 (Rollins founded); public since 1968
B9: Number of brands in portfolio | C9: P1 | D9: 60+
B10: Number of franchisees (total units) | C10: P1 | D10: Franchise: ~85 Critter Control territories. Corporate-operated: Orkin, HomeTeam, Western, Trutech, Saela/Romex/Fox Pest
A11: B. Ownership & PE Structure
B12: Current majority owner | C12: P1 | D12: Public (NYSE: ROL) — Rollins family retains significant ownership
B13: Minority investors / co-investors | C13: P2
B14: Acquisition date / initial investment | C14: P1
B15: Fund vintage / fund size | C15: P2
B16: Anticipated exit window | C16: P2
B17: Prior ownership history | C17: P3
A18: C. Financial Performance
B19: Systemwide sales ($) | C19: P1
B20: Royalty + marketing fund revenue | C20: P1
B21: EBITDA (last 12 months) | C21: P1
B22: EBITDA margin % | C22: P2
B23: Revenue growth rate (YoY) | C23: P2 | D23: 10-K disclosed — see most recent annual report
B24: Most recent valuation / enterprise value | C24: P2 | D24: ~$3.4B market cap
A25: D. Franchisee Unit Economics
B26: Average unit AUV | C26: P1
B27: Average unit EBITDA | C27: P1
B28: Average franchisee tenure | C28: P2
B29: Multi-unit ownership % | C29: P2
B30: Average franchise fee / initial investment | C30: P3
A31: E. Growth & Territory Data
B32: Number of units added (last 3 years) | C32: P1
B33: Number of units closed (last 3 years) | C33: P2
B34: Planned unit openings (next 2 years) | C34: P2
B35: Geographic concentration (top 5 states) | C35: P3
B36: International footprint | C36: P3
A37: F. Technology Stack
B38: Current FSM platform(s) used across network | C38: P1 | D38: ServiceBridge de facto in Critter Control (156% multi-unit penetration). Corporate brands use enterprise systems.
B39: CRM platform used | C39: P2
B40: Telematics / fleet tracking provider | C40: P1
B41: Payment processing / financing provider | C41: P2
...

Sheet Completion Summary
A1: COMPLETION SUMMARY · Track data fill progress
A2: Counts populated vs. total data points per franchisor. Updates as Accel-KKR fills the tabs.
A4: # | B4: FRANCHISOR | C4: PRIORITY | D4: FIELDS POPULATED | E4: TOTAL FIELDS | F4: % COMPLETE
A5: 1 | B5: Neighborly | C5: P1 | D5: =COUNTA('01 Neighborly'!D6:D10)+COUNTA('01 Neighborly'!D12:D17)+COUNTA('01 Neighborly'!D19:D24)+COUNTA('01 Neighborly'!D26:D30)+COUNTA('01 Neighborly'!D32:D36)+COUNTA('01 Neighborly'!D38:D42)+COUNTA('01 Neighborly'!D44:D48) -> 10 | E5: 37 | F5: =D5/E5 -> 0.27027027
A6: 2 | B6: Authority Brands | C6: P1 | D6: =COUNTA('02 Authority Brands'!D6:D10)+COUNTA('02 Authority Brands'!D12:D17)+COUNTA('02 Authority Brands'!D19:D24)+COUNTA('02 Authority Brands'!D26:D30)+COUNTA('02 Authority Brands'!D32:D36)+COUNTA('02 Authority Brands'!D38:D42)+COUNTA('02 Authority Brands'!D44:D48) -> 11 | E6: 37 | F6: =D6/E6 -> 0.2972973
A7: 3 | B7: Empower Brands | C7: P1 | D7: =COUNTA('03 Empower Brands'!D6:D10)+COUNTA('03 Empower Brands'!D12:D17)+COUNTA('03 Empower Brands'!D19:D24)+COUNTA('03 Empower Brands'!D26:D30)+COUNTA('03 Empower Brands'!D32:D36)+COUNTA('03 Empower Brands'!D38:D42)+COUNTA('03 Empower Brands'!D44:D48) -> 7 | E7: 37 | F7: =D7/E7 -> 0.18918919
A8: 4 | B8: Premium Service Brands | C8: P1 | D8: =COUNTA('04 Premium Service Brands'!D6:D10)+COUNTA('04 Premium Service Brands'!D12:D17)+COUNTA('04 Premium Service Brands'!D19:D24)+COUNTA('04 Premium Service Brands'!D26:D30)+COUNTA('04 Premium Service Brands'!D32:D36)+COUNTA('04 Premium Service Brands'!D38:D42)+COUNTA('04 Premium Service Brands'!D44:D48) -> 6 | E8: 37 | F8: =D8/E8 -> 0.16216216
A9: 5 | B9: HomeFront Brands | C9: P1 | D9: =COUNTA('05 HomeFront Brands'!D6:D10)+COUNTA('05 HomeFront Brands'!D12:D17)+COUNTA('05 HomeFront Brands'!D19:D24)+COUNTA('05 HomeFront Brands'!D26:D30)+COUNTA('05 HomeFront Brands'!D32:D36)+COUNTA('05 HomeFront Brands'!D38:D42)+COUNTA('05 HomeFront Brands'!D44:D48) -> 7 | E9: 37 | F9: =D9/E9 -> 0.18918919
A10: 6 | B10: Five Star Franchising | C10: P1 | D10: =COUNTA('06 Five Star Franchising'!D6:D10)+COUNTA('06 Five Star Franchising'!D12:D17)+COUNTA('06 Five Star Franchising'!D19:D24)+COUNTA('06 Five Star Franchising'!D26:D30)+COUNTA('06 Five Star Franchising'!D32:D36)+COUNTA('06 Five Star Franchising'!D38:D42)+COUNTA('06 Five Star Franchising'!D44:D48) -> 6 | E10: 37 | F10: =D10/E10 -> 0.16216216
A11: 7 | B11: ResiBrands | C11: P1 | D11: =COUNTA('07 ResiBrands'!D6:D10)+COUNTA('07 ResiBrands'!D12:D17)+COUNTA('07 ResiBrands'!D19:D24)+COUNTA('07 ResiBrands'!D26:D30)+COUNTA('07 ResiBrands'!D32:D36)+COUNTA('07 ResiBrands'!D38:D42)+COUNTA('07 ResiBrands'!D44:D48) -> 6 | E11: 37 | F11: =D11/E11 -> 0.16216216
A12: 8 | B12: Evive Brands | C12: P2 | D12: =COUNTA('08 Evive Brands'!D6:D10)+COUNTA('08 Evive Brands'!D12:D17)+COUNTA('08 Evive Brands'!D19:D24)+COUNTA('08 Evive Brands'!D26:D30)+COUNTA('08 Evive Brands'!D32:D36)+COUNTA('08 Evive Brands'!D38:D42)+COUNTA('08 Evive Brands'!D44:D48) -> 8 | E12: 37 | F12: =D12/E12 -> 0.21621622
A13: 9 | B13: Threshold Brands | C13: P2 | D13: =COUNTA('09 Threshold Brands'!D6:D10)+COUNTA('09 Threshold Brands'!D12:D17)+COUNTA('09 Threshold Brands'!D19:D24)+COUNTA('09 Threshold Brands'!D26:D30)+COUNTA('09 Threshold Brands'!D32:D36)+COUNTA('09 Threshold Brands'!D38:D42)+COUNTA('09 Threshold Brands'!D44:D48) -> 8 | E13: 37 | F13: =D13/E13 -> 0.21621622
A14: 10 | B14: BELFOR Franchise Group | C14: P2 | D14: =COUNTA('10 BELFOR Franchise Group'!D6:D10)+COUNTA('10 BELFOR Franchise Group'!D12:D17)+COUNTA('10 BELFOR Franchise Group'!D19:D24)+COUNTA('10 BELFOR Franchise Group'!D26:D30)+COUNTA('10 BELFOR Franchise Group'!D32:D36)+COUNTA('10 BELFOR Franchise Group'!D38:D42)+COUNTA('10 BELFOR Franchise Group'!D44:D48) -> 9 | E14: 37 | F14: =D14/E14 -> 0.24324324
A15: 11 | B15: Rollins Inc | C15: P3 | D15: =COUNTA('11 Rollins Inc'!D6:D10)+COUNTA('11 Rollins Inc'!D12:D17)+COUNTA('11 Rollins Inc'!D19:D24)+COUNTA('11 Rollins Inc'!D26:D30)+COUNTA('11 Rollins Inc'!D32:D36)+COUNTA('11 Rollins Inc'!D38:D42)+COUNTA('11 Rollins Inc'!D44:D48) -> 10 | E15: 37 | F15: =D15/E15 -> 0.27027027
A16: TOTAL (all 11 franchisors) | D16: =SUM(D5:D15) -> 88 | E16: 407 | F16: =D16/E16 -> 0.21621622
