Workbook

Sheet Executive Scorecard
A1: EXECUTIVE SCORECARD · ServiceBridge Franchisor GTM Engagement · April – June 2026
A2: Prepared by Velocity GTM Co LLC · Michael Montgomery Flynt Jr · Metrics auto-update as activity is logged across all tabs
B3: METRIC | D3: TARGET | E3: ACTUAL | F3: % TO GOAL | G3: STATUS
B5: PHASE 1 · 30-DAY · DEVELOP
B6: Target: End of April 2026 · Build the foundation for both tracks
B8: TRACK 1 — FRANCHISOR
B9: Franchisors Profiled (deep research complete) | D9: 9 | E9: =COUNTIF('Track 1 · Franchisors'!D4:D12,"TIER 1")+COUNTIF('Track 1 · Franchisors'!D4:D12,"TIER 2")+COUNTIF('Track 1 · Franchisors'!D4:D12,"TIER 3") | F9: =IFERROR(E9/9,0) | G9: =IF(E9>=9,"✅ On Track",IF(E9>=9*0.7,"⚠️ At Risk","🔴 Behind"))
B10: Contacts Mapped (3+ per franchisor = 27 total) | D10: 27 | E10: =0 | F10: =IFERROR(E10/27,0) | G10: =IF(E10>=27,"✅ On Track",IF(E10>=27*0.7,"⚠️ At Risk","🔴 Behind"))
B11: Outreach Sequences Live (both tracks active) | D11: 9 | E11: =COUNTIFS('Track 1 · Franchisors'!L4:L12,"Contacted")+COUNTIFS('Track 1 · Franchisors'!L4:L12,"Replied")+COUNTIFS('Track 1 · Franchisors'!L4:L12,"Call Scheduled")+COUNTIFS('Track 1 · Franchisors'!L4:L12,"Discovery Done")+COUNTIFS('Track 1 · Franchisors'!L4:L12,"Proposal Sent")+COUNTIFS('Track 1 · Franchisors'!L4:L12,"Negotiating")+COUNTIFS('Track 1 · Franchisors'!L4:L12,"Pilot Closed") | F11: =IFERROR(E11/9,0) | G11: =IF(E11>=9,"✅ On Track",IF(E11>=9*0.7,"⚠️ At Risk","🔴 Behind"))
B12: TRACK 2 — FRANCHISEE
B13: Franchisee Brands Scored (all 85 in database) | D13: 85 | E13: =COUNTA('Track 2 · Franchisees'!B4:B88)-COUNTBLANK('Track 2 · Franchisees'!B4:B88) | F13: =IFERROR(E13/85,0) | G13: =IF(E13>=85,"✅ On Track",IF(E13>=85*0.7,"⚠️ At Risk","🔴 Behind"))
B14: Contacts Validated (one per brand) | D14: 85 | E14: =COUNTA('Track 2 · Franchisees'!J4:J88)-COUNTIF('Track 2 · Franchisees'!J4:J88,"(Franchisee Owner)")-COUNTIF('Track 2 · Franchisees'!J4:J88,"(TBD — Research)")-COUNTIF('Track 2 · Franchisees'!J4:J88,"") | F14: =IFERROR(E14/85,0) | G14: =IF(E14>=85,"✅ On Track",IF(E14>=85*0.7,"⚠️ At Risk","🔴 Behind"))
B15: Outreach Sequences Live (brands contacted) | D15: 85 | E15: =COUNTIFS('Track 2 · Franchisees'!L4:L88,"Contacted")+COUNTIFS('Track 2 · Franchisees'!L4:L88,"Replied")+COUNTIFS('Track 2 · Franchisees'!L4:L88,"Call Scheduled")+COUNTIFS('Track 2 · Franchisees'!L4:L88,"Discovery Done")+COUNTIFS('Track 2 · Franchisees'!L4:L88,"Proposal Sent")+COUNTIFS('Track 2 · Franchisees'!L4:L88,"Negotiating")+COUNTIFS('Track 2 · Franchisees'!L4:L88,"Pilot Closed") | F15: =IFERROR(E15/85,0) | G15: =IF(E15>=85,"✅ On Track",IF(E15>=85*0.7,"⚠️ At Risk","🔴 Behind"))
B16: ENGAGEMENT ACTIVITY — CRM LOG
B17: Total Touchpoints Logged (all channels) | D17: 30 | E17: =COUNTA('Engagement Log'!B5:B80)-COUNTBLANK('Engagement Log'!B5:B80) | F17: =IFERROR(E17/30,0) | G17: =IF(E17>=30,"✅ On Track",IF(E17>=30*0.7,"⚠️ At Risk","🔴 Behind"))
B18: Positive Outcomes (replied, calls, meetings) | D18: 5 | E18: =COUNTIF('Engagement Log'!I5:I80,"Replied – Positive")+COUNTIF('Engagement Log'!I5:I80,"Call Scheduled")+COUNTIF('Engagement Log'!I5:I80,"Call Complete")+COUNTIF('Engagement Log'!I5:I80,"Meeting Complete")+COUNTIF('Engagement Log'!I5:I80,"Pilot Agreed") | F18: =IFERROR(E18/5,0) | G18: =IF(E18>=5,"✅ On Track",IF(E18>=5*0.7,"⚠️ At Risk","🔴 Behind"))
B20: PHASE 2 · 60-DAY · ENGAGE
B21: Target: End of May 2026 · Drive active conversations on both tracks
B23: TRACK 1 — FRANCHISOR
B24: Franchisors in Active Conversation | D24: 3 | E24: =COUNTIFS('Track 1 · Franchisors'!L4:L12,"Discovery Done")+COUNTIFS('Track 1 · Franchisors'!L4:L12,"Proposal Sent")+COUNTIFS('Track 1 · Franchisors'!L4:L12,"Negotiating")+COUNTIFS('Track 1 · Franchisors'!L4:L12,"Pilot Closed") | F24: =IFERROR(E24/3,0) | G24: =IF(E24>=3,"✅ On Track",IF(E24>=3*0.7,"⚠️ At Risk","🔴 Behind"))
B25: Mandate Validated (confirmed at franchisor level) | D25: 3 req. | E25: =0 | F25: — | G25: Manual
B26: Franchisor Discovery Calls Completed | D26: 3 | E26: =COUNTIF('Engagement Log'!H5:H80,"Discovery Call") | F26: =IFERROR(E26/3,0) | G26: =IF(E26>=3,"✅ On Track",IF(E26>=3*0.7,"⚠️ At Risk","🔴 Behind"))
B27: Proposals / ROI Models Submitted | D27: 1 | E27: =COUNTIFS('Track 1 · Franchisors'!L4:L12,"Proposal Sent")+COUNTIFS('Track 1 · Franchisors'!L4:L12,"Negotiating") | F27: =IFERROR(E27/1,0) | G27: =IF(E27>=1,"✅ On Track",IF(E27>=1*0.7,"⚠️ At Risk","🔴 Behind"))
B28: TRACK 2 — FRANCHISEE
B29: Franchisees Engaged (in active conversation) | D29: 25 | E29: =COUNTIFS('Track 2 · Franchisees'!L4:L88,"Replied")+COUNTIFS('Track 2 · Franchisees'!L4:L88,"Call Scheduled")+COUNTIFS('Track 2 · Franchisees'!L4:L88,"Discovery Done")+COUNTIFS('Track 2 · Franchisees'!L4:L88,"Proposal Sent")+COUNTIFS('Track 2 · Franchisees'!L4:L88,"Negotiating")+COUNTIFS('Track 2 · Franchisees'!L4:L88,"Pilot Closed") | F29: =IFERROR(E29/25,0) | G29: =IF(E29>=25,"✅ On Track",IF(E29>=25*0.7,"⚠️ At Risk","🔴 Behind"))
B30: Confirmed Next Steps (committed to follow-up) | D30: 10 | E30: =COUNTIFS('Track 2 · Franchisees'!L4:L88,"Call Scheduled")+COUNTIFS('Track 2 · Franchisees'!L4:L88,"Discovery Done")+COUNTIFS('Track 2 · Franchisees'!L4:L88,"Proposal Sent")+COUNTIFS('Track 2 · Franchisees'!L4:L88,"Negotiating")+COUNTIFS('Track 2 · Franchisees'!L4:L88,"Pilot Closed") | F30: =IFERROR(E30/10,0) | G30: =IF(E30>=10,"✅ On Track",IF(E30>=10*0.7,"⚠️ At Risk","🔴 Behind"))
B31: Pilots Seeded (pilot conversation started) | D31: 3–5 | E31: =COUNTIFS('Track 2 · Franchisees'!L4:L88,"Proposal Sent")+COUNTIFS('Track 2 · Franchisees'!L4:L88,"Negotiating")+COUNTIFS('Track 2 · Franchisees'!L4:L88,"Pilot Closed") | F31: — | G31: Manual
B32: HIGH Pilot Potential Accounts Contacted | D32: 15 | E32: =COUNTIFS('Track 2 · Franchisees'!I4:I88,"HIGH",'Track 2 · Franchisees'!L4:L88,"Contacted")+COUNTIFS('Track 2 · Franchisees'!I4:I88,"HIGH",'Track 2 · Franchisees'!L4:L88,"Replied")+COUNTIFS('Track 2 · Franchisees'!I4:I88,"HIGH",'Track 2 · Franchisees'!L4:L88,"Call Scheduled")+COUNTIFS('Track 2 · Franchisees'!I4:I88,"HIGH",'Track 2 · Franchisees'!L4:L88,"Discovery Done")+COUNTIFS('Track 2 · Franchisees'!I4:I88,"HIGH",'Track 2 · Franchisees'!L4:L88,"Proposal Sent")+COUNTIFS('Track 2 · Franchisees'!I4:I88,"HIGH",'Track 2 · Franchisees'!L4:L88,"Pilot Closed") | F32: =IFERROR(E32/15,0) | G32: =IF(E32>=15,"✅ On Track",IF(E32>=15*0.7,"⚠️ At Risk","🔴 Behind"))
B34: PHASE 3 · 90-DAY · CLOSE
B35: Target: End of June 2026 · Close pilots, advance franchisors, deliver playbook
B37: TRACK 1 — FRANCHISOR
B38: Franchisor in Qualified Interest Discussion | D38: 1+ req. | E38: =COUNTIFS('Track 1 · Franchisors'!L4:L12,"Negotiating")+COUNTIFS('Track 1 · Franchisors'!L4:L12,"Pilot Closed") | F38: — | G38: Manual
B39: Franchisor Deal in Progress / Closed | D39: 1 | E39: =COUNTIFS('Track 1 · Franchisors'!L4:L12,"Pilot Closed") | F39: =IFERROR(E39/1,0) | G39: =IF(E39>=1,"✅ On Track",IF(E39>=1*0.7,"⚠️ At Risk","🔴 Behind"))
B40: PE Warm Intros Activated (Charles path) | D40: Manual | E40: =0 | F40: — | G40: Manual
B41: GTM Playbook Delivered | D41: Yes/No | E41: No | F41: — | G41: Manual
B42: TRACK 2 — FRANCHISEE
B43: Pilots Closed (signed agreements) | D43: 2 | E43: =COUNTIFS('Track 2 · Franchisees'!L4:L88,"Pilot Closed") | F43: =IFERROR(E43/2,0) | G43: =IF(E43>=2,"✅ On Track",IF(E43>=2*0.7,"⚠️ At Risk","🔴 Behind"))
B44: Pilots in Active Negotiation | D44: 3 | E44: =COUNTIFS('Track 2 · Franchisees'!L4:L88,"Negotiating") | F44: =IFERROR(E44/3,0) | G44: =IF(E44>=3,"✅ On Track",IF(E44>=3*0.7,"⚠️ At Risk","🔴 Behind"))
B45: Total Pipeline Value Created (Closed + Negotiating) | D45: $50K+ | E45: =0 | F45: — | G45: Manual
B46: Extension Plan Presented to Core Team | D46: Yes/No | E46: No | F46: — | G46: Manual
...

Sheet Changelog v15.6
A1: CRM v15.6 — Validation Changelog
A2: Validated April 29, 2026 by Velocity GTM Co LLC. 9 changes applied to Track 2 · Franchisees sheet.
A3: 2026-05-04 | B3: v15.35 | C3: CRM | D3: Track 2 LinkedIn URL Sync from Alumni Crossover v15 | E3: Synced 24 LinkedIn URLs from validated Alumni Crossover file. Replaced 17 stale/predecessor URLs with current brand president URLs (Aire Serv → Jay Jimenez, Rainbow → Josh Miller, Pestmaster → Bryan Shamhart, etc.) Added 7 new URL entries for previously-unverified contacts (Action Exteriors, Monty's Handyman, etc.). Major correction: TruBlue brand president confirmed as Sean Fitzgerald (linkedin.com/in/seancfitzgerald), NOT Stephen Nichols as previously mis-recorded. | F3: Mike validation | G3: 24 brand cells updated
A4: Date | B4: Row | C4: Brand | D4: Field Changed | E4: Old Value | F4: New Value | G4: Reason for Change
A5: 2026-04-29 20:24 | B5: 40 | C5: USA Insulation | D5: FSM Status | E5: Greenfield | F5: At-Risk SB | G5: Per Andrea Apr 2026: 75% SB penetration but transitioning OFF over next year. Not greenfield — retention/monitor play.
A6: 2026-04-29 20:24 | B6: 40 | C6: USA Insulation | D6: Current FSM Platform | E6: Greenfield / Paper | F6: ServiceBridge (75%, AT-RISK — transitioning off per Andrea Apr 2026) | G6: Andrea confirmed Apr 2026: USA Insulation transitioning off ServiceBridge over the next year. Not greenfield.
A7: 2026-04-29 20:24 | B7: 40 | C7: USA Insulation | D7: Notes | E7: Seasonal scheduling — strong dispatch fit | F7: ⚠️ AT-RISK / RETENTION PLAY — Andrea confirmed Apr 2026: USA Insulation transitioning off ServiceBridge over next year. Posture: dual-track — defend if reversible, reset relationship at brand-corp lev | G7: Added retention-play context per Threshold P2 readiness package.
A8: 2026-04-29 20:24 | B8: 40 | C8: USA Insulation | D8: Combined Score | E8: 84 🟡 QUEUE | F8: 84* ⚠️ RECALIBRATE — at-risk, not greenfield | G8: Score derived from greenfield assumption that does not apply. Flagged for recalibration.
A9: 2026-04-29 20:24 | B9: 37 | C9: BELFOR Property Restoration | D9: FSM Status | E9: Greenfield | F9: Not FSM Scope | G9: BELFOR Property Restoration is the parent restoration business — runs on restoration management software (Xactimate/Symbility), not FSM. Out of ServiceBridge category.
A10: 2026-04-29 20:24 | B10: 37 | C10: BELFOR Property Restoration | D10: Current FSM Platform | E10: Greenfield / Paper | F10: Restoration management software (Xactimate/Symbility ecosystem) — not FSM category | G10: Restoration management is a different software category. Not displaceable by FSM.
A11: 2026-04-29 20:24 | B11: 37 | C11: BELFOR Property Restoration | D11: Combined Score | E11: 116 🔴 LEAD PILOT | F11: EXCLUDE ⛔ NOT FSM SCOPE | G11: Excluded from FSM engagement. Score was based on incorrect greenfield framework.
A12: 2026-04-29 20:24 | B12: 37 | C12: BELFOR Property Restoration | D12: Notes | E12: Large restoration crews — documentation + compliance | F12: ⛔ EXCLUDED — different software ecosystem (restoration management). Engage at parent franchisor level (BELFOR FG) only, not as Stage 2 brand-corp target. | Large restoration crews — documentation + co | G12: Added exclusion rationale.
A13: 2026-04-29 20:24 | B13: 2 | C13: (Header) | D13: Subheader version stamp | E13: Velocity GTM Co LLC · Sorted by parent franchisor · GPS Insight warm accounts highlighted · Pilot potential scored HIGH / MED / LOW | F13: Velocity GTM Co LLC · Sorted by parent franchisor · GPS Insight warm accounts prioritized · v15.6 — validated April 29, 2026 | G13: Version bump and validation date.
A14: 2026-05-04 | B14: v15.36 | C14: CRM | D14: V19 Alumni Crossover Intel Sync — Multi-tab Update | E14: Comprehensive sync of Alumni Crossover v19 intel into CRM across 5 tabs: • Track 1: Updated Col 25 (GPS INSIGHT EXEC CONTACT) for 6 franchisor rows with consolidated warm-path summaries (Neighborly, Empower, ResiBrands, HomeFront, BELFOR, Threshold). Added v19 marker to Col 38 Signal Intel. • Engagement Log: Added 5 new entries (#79-83) — Alumni Crossover ask sent to GPS Insight team; Becky-Mike touch plan kickoff; Beth Toenies LinkedIn connection accepted; Carter Smith handoff to Garrett; Jeff Dudan App State warm-path strategy. • Account Feedback: Updated 11 accounts with [v19 Update] additions to KEY FEEDBACK + NEXT MILESTONE columns. Temperature shift: Empower → 🔥 Hot (Canopy NC State angle). • Signal Intel: Added new V19 Alumni Crossover Intel section with 20 categorized records (Active Engagement, Warm Path, Team Assignment, Status Change, Data Gap, Org Intel) with action/owner/status assignments. • Strategic frame: 'Building off existing relationships is our fastest path to success.' Cold outreach into PE-backed franchisors takes months; warm intro compresses to weeks. Becky-Mike touch plan in development this week to sequence outreach using team alumni hits as warm anchors. Status changes flagged for verification: Ben Lamb (Neighborly CFO) moved Feb 2026, Brad Roberson (Glass Doctor → Fastest Labs) may have left March 2026, Russ Jundt (Empower) retired, Doug Smith (BELFOR) may have left. | F14: Mike + alumni v19 intel | G14: 5 tabs updated · 20 intel records integrated
A16: Validation Summary
A17: ✓ Total brands in Track 2 reviewed: 78
A18: ✓ Portfolio assignments verified — CRM is correct (no misassignments found)
A19: ✓ Score-FSM consistency check passed — no logic errors
A20: ✓ No duplicate brand entries
A21: ✓ All 78 brands have parent franchisor, trade, location, FSM status fields populated
A22: ⚠️ 64 of 78 brands marked "Validate with Andrea" for GPSI customer overlap — REQUIRES GPSI team query
A23: ⚠️ ~68 of 78 brands have "TBD" for Owner/Decision Maker — REQUIRES Andrea/Marketing team intel
A24: ⚠️ 2 substantive corrections applied: USA Insulation (At-Risk, not Greenfield) + BELFOR Property Restoration (Not FSM scope)
A26: NEXT STEPS for full data closure:
A27: 1. GPSI customer database query for all 78 brands → fills GPSI Customer column + Telematics column
A28: 2. Brand-corp leadership intel from Andrea/Marketing team → fills Owner/DM column for ~68 brands
... A32: Track 1 · Franchisors V2 Realignment (April 29, 2026)
A33: 2026-04-29 | B33: 4-14 | C33: NEIGHBORLY | D33: V2 Track 1 position | E33: 9 | F33: 1 | G33: V2 ranking
A34: 2026-04-29 | B34: 4-14 | C34: NEIGHBORLY | D34: TIER label | E34: TIER 3 | F34: P1 #1 · PE-GATED | G34: V2 character label
A35: 2026-04-29 | B35: 4-14 | C35: NEIGHBORLY | D35: FRANCHISOR SCORE | E35: 39 ⚪ BUILD | F35: 76.5 🔴 PE-GATED — DO NOT APPROACH DIRECT | G35: V2 score (greenfield-weighted)
A36: 2026-04-29 | B36: 4-14 | C36: AUTHORITY BRANDS | D36: V2 Track 1 position | E36: 8 | F36: 2 | G36: V2 ranking
A37: 2026-04-29 | B37: 4-14 | C37: AUTHORITY BRANDS | D37: TIER label | E37: TIER 3 | F37: P1 #2 · DISPLACEMENT-READY | G37: V2 character label
A38: 2026-04-29 | B38: 4-14 | C38: AUTHORITY BRANDS | D38: FRANCHISOR SCORE | E38: 61 🟡 ACTIVE | F38: 68.5 🟡 ACTIVE | G38: V2 score (greenfield-weighted)
A39: 2026-04-29 | B39: 4-14 | C39: EMPOWER BRANDS | D39: V2 Track 1 position | E39: 3 | F39: 3 | G39: V2 ranking
A40: 2026-04-29 | B40: 4-14 | C40: EMPOWER BRANDS | D40: TIER label | E40: TIER 1 | F40: P1 #3 · GREENFIELD-LED | G40: V2 character label
A41: 2026-04-29 | B41: 4-14 | C41: EMPOWER BRANDS | D41: FRANCHISOR SCORE | E41: 60 🟡 ACTIVE | F41: 66.2 🟡 ACTIVE | G41: V2 score (greenfield-weighted)
A42: 2026-04-29 | B42: 4-14 | C42: RESIBRANDS | D42: V2 Track 1 position | E42: 5 | F42: 4 | G42: V2 ranking
A43: 2026-04-29 | B43: 4-14 | C43: RESIBRANDS | D43: TIER label | E43: TIER 2 | F43: P1 #4 · FAST-CYCLE | G43: V2 character label
A44: 2026-04-29 | B44: 4-14 | C44: RESIBRANDS | D44: FRANCHISOR SCORE | E44: 58 🟡 ACTIVE | F44: 60.2 🟢 ACTIVE | G44: V2 score (greenfield-weighted)
... A60: 2026-04-29 | B60: 4-14 | C60: THRESHOLD | D60: FRANCHISOR SCORE | E60: 73 🔴 MOVE NOW | F60: P2 SET | G60: P2 set qualitatively classified
...

Sheet PE Relationship Map
A1: PE RELATIONSHIP MAP · GPS Insight Warm Introduction Paths · ServiceBridge GTM Engagement
A2: Velocity GTM Co LLC · These introductions require GPS Insight coordination · Every row is a GPS Insight ask tracked to completion
A3: 🔑 Each row on this tab represents an introduction path that runs through GPS Insight's PE network · Status updated as introductions progress
B5: WHY THIS TAB EXISTS
B6: A warm PE-level introduction compresses a 6-month enterprise sales cycle to 6 weeks. Accel-KKR (GPS Insight's backer) has portfolio relationships, co-investment networks, and operating partner connections that give you an immediate credibility bridge to the PE firms backing your 9 priority franchisor accounts. None of these introductions happen without Charles Layne. This tab tracks every PE relationship, who at GPS Insight owns it, what the ask is, and where the introduction stands.
B8: PE FIRM | C8: FUND TYPE & AUM | D8: PORTFOLIO COMPANY | E8: GPS INSIGHT OWNER | F8: PE TARGET CONTACT (Named Individuals) | G8: INTRO PATH | H8: PRIORITY | I8: INTRO STATUS | J8: LAST GPS ACTION | K8: NEXT GPS ACTION NEEDED | L8: NEXT DATE | M8: NOTES / INTELLIGENCE | N8: PE DEAL TEAM FOCAL POINTS ← Researched contacts
B10: SECTION 1 · ACCEL-KKR NETWORK · GPS Insight's Own PE Backer · Highest Leverage
B11: Accel-KKR backed GPS Insight. This is your warmest possible intro path. Charles Layne has direct relationships with the AKKR deal team.
B13: Accel-KKR | C13: Tech-Focused PE ~$10B+ AUM | D13: GPS Insight / ServiceBridge (Portfolio Company) | E13: GPS Insight (Charles Layne, CEO) | F13: Accel-KKR Internal (GPS Insight board-level) | G13: Charles Layne → AKKR deal team → PE portfolio introductions | H13: 🔴 Critical | I13: Not Started | K13: 📞 On me — calling Charles. Asking GPS Insight to brief AKKR and open intro paths to the four PE firms. | L13: Week 1 | M13: GPS Insight backer. Charles Layne has direct AKKR deal team relationships. This single conversation unlocks all downstream PE intros. | N13: TBD — Accel-KKR deal team partner for GPS Insight ← Charles Layne is the direct relationship Accel-KKR = GPS Insight's own PE backer — highest leverage intro chain
B14: KKR | C14: Large-Cap PE $349B+ AUM | D14: Neighborly (16 brands, 13,259 techs) | E14: GPS Insight (Charles Layne, CEO) | F14: Felix Gernburd Managing Director, KKR Led Neighborly acquisition 2021 North American PE fund | G14: Charles → Accel-KKR deal team → KKR deal team → Felix Gernburd | H14: 🔴 Critical | I14: Not Started | K14: Flag to Charles that the Accel-KKR → KKR path is the play for Neighborly. Ask him to request a warm intro to Felix Gernburd — KKR Partner, Neighborly board seat. | L14: Week 1 | M14: KKR acquired Neighborly (Jul 2021) from Harvest Partners. Felix Gernburd is on Neighborly board. ST renewal window 2025–2027. One KKR-level conversation positions us for that window. | N14: Felix Gernburd — Managing Director, KKR Named in KKR/Neighborly acquisition press release as deal lead Intro path: Charles Layne → Accel-KKR → KKR → Felix Gernburd ⚠️ DO NOT cold outreach — PE intro only
B16: SECTION 2 · TIER 1 FRANCHISOR PE BACKERS · Active Introduction Requests
B17: These PE firms back your Tier 1 accounts. A single intro at the PE level is worth months of direct franchisor outreach.
B19: American Securities | C19: Mid-Market PE ~$10B AUM | D19: BELFOR Franchise Group (14 brands, 9,250 techs) | E19: GPS Insight (Charles Layne, CEO) | F19: David Horing Co-Chair Investment Committee Director, BELFOR (since 1995) Managing Member, active funds Ryan Nolan Director, BELFOR Joined 2017, ex-JPMorgan David Musicant Director, BELFOR Joined 2011, deal sourcing Ex-BofA/Merrill Lynch MD Loren Easton Chairman, BELFOR board | G19: Charles → AKKR deal team → American Securities operating partners | H19: 🔴 Critical | I19: Not Started | K19: Week 1 — Charles Layne call. Ask him to surface any AKKR → American Securities relationship. American Securities has board representation at BELFOR — an operating partner intro skips directly to the mandate decision. | L19: Week 1 | M19: American Securities board is active on ops improvement at BELFOR. Tech standardization directly supports their portfolio thesis. BELFOR sold 30 new franchise territories Dec 2024 — mandate now = every new franchisee is a guaranteed adoption. | N19: PRIMARY: David Horing (Co-Chair IC, Director BELFOR since 1995) OPERATIONAL: Ryan Nolan (Director BELFOR, joined 2017, ex-JPMorgan) RELATIONSHIPS: David Musicant (Director BELFOR, deal sourcing/capital markets) CHAIRMAN: Loren Easton (BELFOR board chairman) INTRO PATH: Charles Layne → Accel-KKR → American Securities Source: american-securities.com team pages (confirmed)
B20: The Riverside Company | C20: Global Mid-Market PE $13B+ AUM | D20: Threshold Brands (10 brands, 6,250 techs) | E20: GPS Insight (Charles Layne, CEO) | F20: Loren Schlachet Managing Partner, Riverside Leads Threshold platform Brian Sauer Senior Partner, Riverside Named on Threshold press releases Steve Rice Principal Caroline Quoyeser Assistant Vice President Deniz Oran Associate Tom Silk Operating Partner Chrissie Yim Finance Director | G20: Charles → AKKR deal team → Riverside Company LP or operating partner relationship | H20: 🟡 High | I20: Not Started | K20: Once the AKKR brief is confirmed, ask Charles to surface any Riverside connection through the PE network. Riverside is approaching exit window — technology standardization improves the EBITDA multiple. | L20: Week 2 | M20: Threshold is Riverside's home services platform (formed 2021). Glassdoor shows high turnover and EBITDA pressure from Riverside. LP-reportable tech standardization is the pitch to the PE firm, not to Hagan Kappler. | N20: PRIMARY: Loren Schlachet (Managing Partner — leads Threshold platform) DEAL LEAD: Brian Sauer (Senior Partner — named on all Threshold add-on releases) OPERATIONAL: Steve Rice (Principal) + Caroline Quoyeser (AVP) + Deniz Oran (Associate) FINANCE: Chrissie Yim (Finance Director) SOURCING: Jeremy Holland (Partner) + Connor McLaughlin (VP Origination) Source: Riverside press release — Miracle Method add-on (Dec 2023)
B21: MidOcean Partners | C21: Mid-Market PE $6B+ AUM | D21: Empower Brands (10 brands, 5,150 techs) | E21: GPS Insight (Charles Layne, CEO) | F21: Eric Roth Principal/Partner, MidOcean Covers Empower Brands Christopher M. Grandpre Operating Partner, MidOcean Chairman, Empower Brands 30+ yrs franchise M&A Founded Outdoor Living Brands 2008 | G21: Charles → AKKR deal team → MidOcean operating partner | H21: 🟡 High | I21: Not Started | K21: Ask Charles about MidOcean connection through Charles / AKKR. MidOcean invested in Empower Dec 2020 — approaching exit window. EBITDA improvement before exit is the story. | L21: Week 2 | M21: MidOcean invested in Empower Brands Dec 2020. Typical hold 5–7 years puts exit window at 2025–2027. First-mover FSM standardization documented before exit = multiple expansion story for MidOcean LPs. | N21: PRIMARY: Eric Roth (covers Empower Brands at MidOcean — confirmed on MidOcean website) OPERATING: Christopher M. Grandpre (Operating Partner + Chairman of Empower Brands) → Founded Outdoor Living Brands 2008 (precursor to Empower) → 30+ years franchise M&A / investment banking INTRO PATH: Charles Layne → MidOcean → Eric Roth or Grandpre Source: midoceanpartners.com + The Joint Corp. press release (May 2025)
B23: SECTION 3 · TIER 2 FRANCHISOR PE BACKERS · Build Relationships in Parallel
B24: Smaller or founder-backed platforms. PE path may be lighter — but still surface any connections through Charles before going cold.
B26: Susquehanna Private Capital | C26: Growth Equity (Susquehanna Int'l Group) | D26: Premium Service Brands (8 brands, 4,950 techs) | E26: GPS Insight (Charles Layne, CEO) | F26: Kyle Squillario Co-Head, Susquehanna Private Capital Named in PSB deal announcement SPC Team: 7 people total 2 Partners, 5 Principals Bala Cynwyd PA | G26: Charles → AKKR → Susquehanna Private Capital connection (if any) | H26: 🔵 Medium | I26: Not Started | K26: Check with Charles if AKKR has any Susquehanna / SGE connection. If not, direct approach to Paul Flick (CEO) is the primary path — SGE is growth equity, not traditional PE, so the founder is the decision-maker. | L26: Week 2 | M26: Susquehanna Private Capital is the investment arm of Susquehanna International Group. PSB is founder-led with PE backing — Paul Flick still runs the business. Direct CEO outreach is the backup if PE path yields nothing. | N26: PRIMARY: Kyle Squillario (Co-Head, SPC — quoted in PSB press release 2021) FIRM: Susquehanna Private Capital — funded by founders of Susquehanna Int'l Group SPC SIZE: ~7 person team, 2 partners — small firm, direct access INTRO: Charles Layne → SPC → Kyle Squillario Source: BusinessWire PSB/SPC announcement (March 2021)
B27: Princeton Equity Group | C27: Franchise-Focused PE Franchise-only investor | D27: Five Star Franchising (5 brands, 2,350 techs) | E27: GPS Insight (Charles Layne, CEO) | F27: Derek DeBenedetto Princeton Equity Group Email: derek@princetonequity.com IFA/conference meeting contact Paul Kuppich Partner (joined 2025) Capital formation focus | G27: Charles → AKKR → Princeton Equity (franchise-focused PE — likely known in network) | H27: 🔵 Medium | I27: Not Started | K27: Week 2 — Princeton Equity exclusively invests in franchise companies — very tight network. Ask Charles if AKKR has any Princeton connection. Year 5 of investment means exit pressure building. | L27: Week 2 | M27: Princeton Equity Group exclusively invests in franchisors and multi-unit companies. Five Star is in Year 5 (invested Jun 2021). EBITDA improvement documented now = higher exit multiple for Princeton. Scott Abbott (CEO) is founder — direct outreach is solid backup. | N27: MEETING CONTACT: Derek DeBenedetto (derek@princetonequity.com) → Listed as IFA 2026 meeting contact in Princeton Year in Review PARTNER: Paul Kuppich (joined 2025 — capital formation + investor relations) FIRM CONTEXT: Princeton invested 2021, Five Star in Year 5 — exit window approaching → ~$350M deployed 2025 across 3 new platforms INTRO PATH: Charles Layne → Princeton Equity → Derek DeBenedetto Source: Princeton 2025 Year in Review + LinkedIn announcement
B28: Dudan Group | C28: Family Office (Founder Capital) | D28: HomeFront Brands (5 brands, 2,550 techs) | E28: GPS Insight (Charles Layne, CEO) | F28: Jeff Dudan Chairman & CEO, HomeFront Founder, Dudan Group Forbes contributor, podcaster Zack Dudan CGO, HomeFront Brands Family office — no external PE team | G28: Direct — Jeff Dudan is both the PE backer AND the CEO. No intermediary needed. | H28: ⚪ Low | I28: Not Started | K28: NO GPS INTRO NEEDED: Jeff Dudan controls both the capital and the operating company. Approach directly. This is the one account where PE intro is not the accelerant — the CEO relationship is. | L28: Week 2 | M28: Dudan Group is Jeff Dudan's family office. He is Chairman + CEO. Direct LinkedIn / podcast outreach to Jeff is faster than any PE path. Note for Charles: no intro needed here. | N28: FAMILY OFFICE: Dudan Group = Jeff Dudan's personal capital — no external PE team DIRECT APPROACH: Jeff Dudan is both PE backer AND operating CEO → Forbes contributor, podcaster — content/thought leadership angle OPERATIONAL: Zack Dudan (CGO) = franchise operations + Homecoming vendor path NO PE INTRO NEEDED — direct approach is the right path Source: HomeFront public filings + Forbes contributor profile
B30: SECTION 4 · TIER 3 FRANCHISOR PE BACKERS · Long Cycle · Relationship Play
B31: Authority Brands and Neighborly have large PE backers. The cycle is long — but the deal size is enormous. Build the relationship now.
B33: Apax Partners + BCI | C33: Large-Cap PE Apax $60B+ · BCI C$211B | D33: Authority Brands (12 brands, 12,098 techs) | E33: GPS Insight (Charles Layne, CEO) | F33: Ashish Karandikar Partner, Apax Partners Led Authority Brands acquisition 2018 Quoted in deal press release BCI (minority stake 2022) British Columbia Investment Mgmt Corp | G33: Charles → AKKR deal team → Apax Partners relationship (LP or co-invest level) | H33: 🟡 High | I33: Not Started | K33: WEEK 1 (research): Ask Charles if AKKR has any LP overlap with Apax fund. Apax explicitly cited 'digitalization' as the AB investment thesis — that is ServiceBridge's positioning. BCI co-invested Sep 2022. | L33: Week 1 (research) | M33: Apax acquired Authority Brands Sep 2017. BCI co-invested Sep 2022 for 'technology transformation.' Apax partner Ashish Karandikar led the deal. Tij Bedi (CTO) was hired Aug 2024 — the tech agenda is active. A PE-level intro to Apax gets us to Tij Bedi much faster. | N33: APAX LEAD: Ashish Karandikar (Partner, Apax — quoted as deal lead in 2018 acquisition) → 'We have been attracted to the home services market for some time' BCI: British Columbia Investment Management Corp (significant minority stake, Sep 2022) → Largest institutional investor in Canada INTRO PATH: Charles Layne → Apax → Ashish Karandikar NOTE: Apax-focused on digitisation/tech for Authority — CTO Tij Bedi (Aug 2024) is the signal Source: Apax.com + PRNewswire acquisition announcement (Sep 2018)
B34: KKR (Neighborly) | C34: Already covered in Section 1 $349B+ AUM | D34: Neighborly (16 brands, 13,259 techs) | E34: GPS Insight (Charles Layne, CEO) | F34: Felix Gernburd Managing Director, KKR Led Neighborly acquisition 2021 ⚠️ DO NOT approach direct | G34: See Section 1 — same KKR path. Do not duplicate effort. | H34: 🔴 Critical | I34: Not Started | K34: ↑ Same KKR path as Section 1 — no separate ask needed. Tracking there. | L34: Week 1 | M34: Neighborly is tracked in Section 1 under the KKR relationship. This row is a reminder that Neighborly PE path and Authority Brands PE path are separate KKR / Apax conversations. | N34: Same as Section 1 — Felix Gernburd is the KKR Neighborly contact ⚠️ DO NOT approach direct under any circumstances INTRO PATH ONLY: Charles Layne → Accel-KKR → KKR → Felix Gernburd Source: KKR/Neighborly acquisition press release BusinessWire (July 2021)
B36: GPS INSIGHT ACTION SUMMARY · The Specific Asks for Charles Layne by Week
B38: WEEK | C38: GPS CONTACT | E38: THE ASK | I38: FOR ACCOUNT | K38: URGENCY | L38: STATUS
B39: Week 1 | C39: GPS Insight (Charles Layne, CEO) | E39: Brief the Accel-KKR deal team on the ServiceBridge GTM initiative. Need AKKR to facilitate PE-level introductions to American Securities (BELFOR), Riverside (Threshold), MidOcean (Empower), and KKR (Neighborly). | I39: ALL 9 FRANCHISORS | K39: 🔴 Critical | L39: Not Started
B40: Week 1 | C40: GPS Insight (Charles Layne, CEO) | E40: Specific KKR ask: Ask for Accel-KKR → KKR deal team intro to Felix Gernburd (KKR Partner / Neighborly Board). One call at the KKR level positions ServiceBridge for the Neighborly ST contract renewal window 2025–2027. | I40: NEIGHBORLY | K40: 🔴 Critical | L40: Not Started
B41: Week 1 | C41: GPS Insight (Garrett Else, CFO) | E41: Schedule 30-minute session to walk through the Insight Engine ROI model assumptions. Garrett's sign-off validates the financial narrative before we take it external to any PE operating partner or franchisor CFO. | I41: ALL ACCOUNTS (ROI Model) | K41: 🔴 Critical | L41: Not Started
B42: Week 1 | C42: GPS Insight (Andrea Rowan, GM) | E42: Connect Mike Flynt with Angie (GPS Insight data strategist) to obtain the micro-franchise company list. This expands Track 2 pipeline beyond the current 85-brand database. | I42: TRACK 2 FRANCHISEE | K42: 🟡 High | L42: Not Started
B43: Week 1 | C43: GPS Insight (Andrea Rowan, GM) | E43: Get the GPS Insight existing telematics client list for cross-referencing against all 9 franchisor accounts. Required conflict check before any outreach begins. | I43: ALL 9 FRANCHISORS | K43: 🔴 Critical | L43: Not Started
B44: Week 2 | C44: GPS Insight (Charles Layne, CEO) | E44: Follow-up on AKKR intro request. Confirm which PE firms have responded and whether any calls are scheduled. If American Securities intro is confirmed, brief Mike before the call. | I44: BELFOR American Securities | K44: 🟡 High | L44: Not Started
B45: Week 2 | C45: GPS Insight (Charles Layne, CEO) | E45: 🔍 On me to check whether there's any Apax Partners (Authority Brands backer) connection through AKKR LP network or co-investment relationships. Apax cited 'digitalization' as their Authority Brands investment thesis — perfect alignment. | I45: AUTHORITY BRANDS Apax Partners | K45: 🟡 High | L45: Not Started
B46: Week 3 | C46: GPS Insight (Garrett Else, CFO) | E46: ROI model sign-off — confirm which assumptions are cleared for external use. Garrett's endorsement as GPS Insight CFO is the credibility layer when the model goes in front of a PE operating partner or franchisor CFO. | I46: ALL ACCOUNTS (ROI Model) | K46: 🔴 Critical | L46: Not Started
B47: Week 4 | C47: GPS Insight (Charles Layne, CEO) | E47: 30-Day check-in: Where do the PE intro paths stand? Which firms have responded? Is a KKR / Felix Gernburd call on the calendar? Any additional PE relationships to activate in Month 2? | I47: ALL PE PATHS | K47: 🟡 High | L47: Not Started
B48: Month 2 | C48: GPS Insight (Charles Layne, CEO) | E48: If Accel-KKR intro has not yet produced a franchisor meeting: ask Charles to make a direct personal call to the PE operating partner. His personal relationship is the accelerant — not a formal intro request. | I48: STALLED ACCOUNTS | K48: 🔵 Medium | L48: Not Started
A50: Prepared by Velocity GTM Co LLC on behalf of GPS Insight / ServiceBridge · Michael Montgomery Flynt Jr · 919.434.6720 · mflyntjr@gmail.com · Confidential · April 2026

Sheet Track 1 · Franchisors
A1: TOP FRANCHISOR ACCOUNTS · Track 1 (P1 ×7) + P2 Set (×3) · V2 Greenfield-Weighted Ranking
A2: Velocity GTM Co LLC · GPS Insight / ServiceBridge Engagement · V2 Ranking April 28, 2026 · CRM v15.6 — validated April 29, 2026
A3: # | B3: FRANCHISOR | C3: PE BACKER | D3: TIER | E3: BRANDS | F3: TECHS | G3: ARR EST. | H3: CEO | I3: CFO | J3: COO / PRESIDENT | K3: BD / FRANCHISE DEV | L3: ENGAGEMENT STATUS | M3: LAST CONTACT | N3: NEXT STEP | O3: NEXT DATE | P3: GPS INSIGHT SUPPORT | Q3: NOTES | R3: ANNUAL CONVENTION | S3: VENDORS / PARTNERS INVITED? | T3: INSURANCE PROGRAM / CARRIER | U3: INSURANCE GTM ANGLE | V3: FDD INTEL (Items 8·11·19) | W3: INSIGHT ENGINE INPUTS ← Pre-populate ROI Calc | X3: FRANCHISOR SCORE / 100 | Y3: GPS INSIGHT EXEC CONTACT ← Internal intro path | Z3: GREENFIELD SCORE (V2 · 20%) | AA3: NETWORK SCORE (V2 · 15%) | AB3: PE SCORE (V2 · 15%) | AC3: DM ACCESS SCORE (V2 · 15%) | AD3: URGENCY SCORE (V2 · 15%) | AE3: DISPLACEMENT SCORE (V2 · 10%) | AF3: C/B MIX SCORE (V2 · 10%) | AG3: KEY CONTACTS LINKEDIN URLS | AH3: FSM / TELEMATICS / INSURANCE COMMENTS | AI3: EVENTS THEY ATTEND / SPEAK AT | AJ3: HOW TO ENGAGE PLAYBOOK SUMMARY | AK3: EXPANDED CONTACTS | AL3: SIGNAL INTEL (compressed · see Signal Intel tab for full) | AM3: EDUCATION (College / University / Trade School)
A4: 1 | B4: NEIGHBORLY | C4: KKR ($349B+ AUM) | D4: P1 #1 · PE-GATED | E4: 16 | F4: 13259 | G4: $198K | H4: Mike Davis CEO (joined Jul 2024) | I4: Benjamin Lamb CFO (joined May 2025) | J4: Jason Himber Group President, Repair Brands | K4: Felix Gernburd KKR Partner / Board ← PE TARGET | N4: Flag to Charles — KKR intro is Week 1 GPS ask | O4: Week 1 (GPS only) | P4: GPS: THIS IS THE #1 GPS ACTION — Charles → Accel-KKR → KKR → Felix Gernburd. DO NOT approach Neighborly direct. | Q4: Gagan Sinha = CIO (joined Sep 2025). ST renewal window 2025–2027. PE play only. | R4: Neighborly Reunion · Oct 2025 held Nashville — next ~Oct 2026 Nashville. DO NOT attend without PE intro. | S4: ✅ Yes — vendor partners attend | T4: ProTradeNet preferred insurance broker (confirmed — ~170 vendors incl. insurance brokers). Validate specific broker via FDD. | U4: 🟡 Medium — ProTradeNet broker is warm intro path to COO/CFO. PE intro only. | V4: SOURCE: Mr. Rooter FDD (franchiseba.com 2025) / Aire Serv FDD 2025 / ProTradeNet confirmed via neighborlybrands.com ITEM 11 — Technology: ServiceTitan explicitly named as required software system across all core brands. On ST since 2012 (Mr. Handyman, Aire Serv, Mr. Rooter, Mr. Electric per ServiceTitan press release). ITEM 8 — Vendors: ProTradeNet ~170 preferred vendors including insurance brokers. Specific broker named in brand-level FDDs. Broker = warm intro path to COO/CFO. ITEM 19 — Aire Serv 2025: 158 reporting businesses, 1/1/24-12/31/24 per FDD. Full financials behind paywall. ⚠️ DO NOT APPROACH DIRECT. PE intro only via Charles → KKR → Felix Gernburd. ST RENEWAL WINDOW: 2025-2027. Only leverage is PE relationship. | W4: 📊 USE INSIGHT ENGINE → ROI Calculator tab ⚠️ DO NOT RUN INSIGHT ENGINE until PE intro confirmed. IF/WHEN PE intro secured, pre-populate: • Technicians: 13,259 • Avg Jobs/Tech/Day: 5 (mature ST-optimized system) • Avg Revenue/Job: $400 • Focus: ST renewal window — Telematics angle via GPS Insight Conversation is about GPS Insight telematics (Smart Fleet USA contract renewal), not ServiceBridge FSM displacement. 3-Way Scenario: KKR exit at 10-12x multiple. | X4: 76.5 🔴 PE-GATED — DO NOT APPROACH DIRECT | Y4: WARM-PATH STATUS (05/04/2026): Mike's active angles to existing leadership: • Mike Davis (Corporate): I have a 1st connection with a former colleague I will investigate. ⚠️ STATUS CHANGES TO VERIFY: • Benjamin Lamb (Corporate): It appears Ben moved Feb. 2026. • Brad Roberson (Glass Doctor (prior)): It appears Brad may of just left business this March 2026 Full alumni intel: see Alumni Crossover GPS Insight v19 + Signal Intel tab v19 update. Becky-Mike touch plan in development for warm-anchor outreach sequencing. | Z4: 4/20 20 (limited; ST mandate caps) | AA4: 14/15 90 (13,259 techs — largest in P1) | AB4: 13/15 85 (KKR — active investor, exit-driven) | AC4: 13/15 85 (Charles Layne → Accel-KKR → KKR warm path) | AD4: 15/15 95 (highest — ST renewals 2025-2027 + KKR window) | AE4: 5/10 50 (ST partial mandate, displaceable on non-ST brands) | AF4: 8/10 80 (consumer-led mix) | AG4: KEY LINKEDIN URLS (UPDATED v15.34): 🎯 PRIMARY TARGET — GAGAN SINHA (CIO since Sept 2025): LinkedIn: linkedin.com/in/gagansinha/ ⭐⭐⭐ Harvard MS Mgmt 2011-2013. From Bloomin' Brands. STILL FORMING FSM ROADMAP. #1 OVERALL TARGET IN ENTIRE DATASET. EXECUTIVES: • Mike Davis (CEO July 2024): linkedin.com/in/mcardavis Ex-Mathnasium/Valpak/UMG. Irving TX. • Benjamin Lamb (CFO May 2025): linkedin.com/in/benlamb-finance/ Baylor BBA Finance/Econ ⭐ • Brad Stevenson (CDO): linkedin.com/in/bradstevenson1/ Texas A&M College Station BS Kinesiology 1991-96 ⭐ MillerCoors career since 1996. • Stacy Lynn Bourgeois (CMO): linkedin.com/in/stacy-lynn-bourgeois/ Northwestern Medill MS + Florida State BA ⭐⭐ • Matt Crowley (Group Pres-Specialty): linkedin.com/in/matt-crowley-usc/ USC Marshall MBA ⭐ Ex-Valpak EVP. • Georgeanne Erickson (Group Pres-Maintain): linkedin.com/in/georgeanne-erickson/ Pending school. Ex-CMO Fogo de Chão. • Jason Himber (Group Pres-Repair): linkedin.com/in/jason-himber/ Pending school verification. WARM PATH (PE-GATED): • Felix Gernburd (KKR Partner / Board): linkedin.com/in/felix-gernburd/ ← PE TARGET via Accel-KKR network • David Brandon (Neighborly Board / KKR Operating Partner): linkedin.com/in/david-brandon/ Ex-CEO Domino's, Toys R Us, Univ Michigan AD ⭐ U Michigan KEY BRAND PRESIDENTS: • Glenn Lewis CFE (Mr. Appliance): linkedin.com/in/glenn-lewis-cfe-28347913/ Baylor ⭐ • Josh McCormick (Mr. Electric, returned Aug 2025): linkedin.com/in/joshmccormickneighborly/ Baylor BBA ⭐ • Brian Meussner (Molly Maid + Mr. Handyman dual brand NEW Jan 2026): linkedin.com/in/brian-meussner-43b22b7/ Central Michigan U ⭐ • Susan McIntosh (Lawn Pride): linkedin.com/in/susanmcintoshneighborly/ Cardinal Ritter HS — operator path 30+ yrs ⭐ • Chris Bruno CFE (Window Genie): linkedin.com/in/chris-bruno-cfe-b895122a1/ Tarleton State ⭐ • Evan Brody (Mosquito Joe): linkedin.com/in/evansbrody/ Olin/WashU ⭐ • Mike Brickner (Precision Door): linkedin.com/in/mike-brickner-precision/ Columbia College ⭐ • Justin Penard (Grout Medic VP FD): linkedin.com/in/justinpenard/ Texas Tech ⭐ | AH4: ★ FSM / TECH / DIGITAL TRANSFORMATION QUOTES ★ Felix Gernburd (KKR Partner, Neighborly press release): "Mike will guide the execution of key enterprise initiatives and the DIGITAL TRANSFORMATION IN PROGRESS aimed to elevate Neighborly as a trusted provider to customers and an attractive investment for prospective franchise owners." → KKR PUBLICLY committed to digital transformation. This is the warm-intro hook. Mike Davis (LinkedIn 2024): "Industry-leading NPS scores across most of our brands - making Fans! A growing percentage of multi-brand customers - USING MARTECH TO CONNECT THE BRANDS and consumer trust - Loyalty that compounds." → Davis is publicly investing in cross-brand data infra. ServiceBridge job-level data feeds martech. Davis (Reunion 2024): "You grow companies by growing believers." "Don't just win customers. Create fans." | AI4: Neighborly Reunion ~Oct 2026 Likely Nashville (Gaylord Opryland) 16 brands + vendor partners attend ★ DO NOT attend without KKR intro IFA Annual Convention (Feb) Brad Stevenson (CDO) on IFA board FLDC Atlanta (Oct 6-8, 2026) Davis likely speaker 👉 See Event Intelligence tab for full schedule + opportunity analysis | AJ4: ENTRY: KKR PE intro only — NO direct approach. CHANNEL: Charles → Accel-KKR → KKR → Felix Gernburd → Davis introduction. ANGLE: GPS Insight telematics conversation FIRST (Smart Fleet conflict needs Mike Davis or Gagan Sinha as decision authority). NOT ServiceBridge FSM — ServiceTitan is locked in at brand level. TIMING: Week 1 GPS Insight ask only. No outreach until warm intro confirmed. Davis tenure (since Jul 2024) + Lamb (since May 2025) = both still in honeymoon period. | AK4: NEIGHBORLY BRAND-LEVEL ROSTER: Aire Serv: Jay Jimenez (Brand Pres NEW Apr 2026, was Brad Roberson) Frederick Roberts (Operations Consultant) Glass Doctor: Gabe Lopez (Brand Pres) Lawn Pride: Susan McIntosh (Brand Pres) Molly Maid: Michael Silva-Nash (Brand Pres) Mosquito Joe: Evan Brody (Brand Pres) Mr. Appliance: Glenn Lewis (Brand Pres) Mr. Electric: Josh McCormick (Brand Pres) Mr. Handyman: Brian Meussner (Brand Pres) Mr. Rooter: Matt Kunz (Brand Pres since 2023) Doyle James (former pres) Precision Garage Door: Mike Brickner (Brand Pres) Rainbow Restoration: Josh Miller (Brand Pres) Window Genie: Chris Bruno (Brand Pres) Five Star Painting: David Sutter (Brand Pres per 2023 video) Mary Kay Liston (former pres) Matt Phillips (former pres, then Neighborly COO) Amy Davis (VP Operations) Michael & Joy Nungesser (2024 Franchise Owners of the Year) Cindy Praesal, Anthony Kulikowski, Amado Cano, Mark Lambert (featured franchisees) Junk King: Vera Peterson (Interim Brand Pres) + Lisa Merry (former) Michael Andreacchi (Co-Founder, Investor + Brand Ambassador) Dryer Vent Wizard: Kevin Busch (Brand Pres) HouseMaster: Nancy Shipley (Brand Pres) Portland Glass: Sarah Frohnhoefer (Brand Pres) ProTradeNet: Brandi Haslam (Brand Pres) Real Property Management: Jeff Pepperney (Brand Pres) ShelfGenie: Tony Ditzler (Brand Pres) Grounds Guys: Lori Johnson (Brand Pres) Group Presidents: • Vera Peterson (Group Pres Maintain cluster: Dryer Vent, Molly Maid, Window Genie, Junk King, Five Star Painting, Mosquito Joe, Grounds Guys, Mr. Appliance) • Georgeanne Erickson (Group Pres — newer arrival) • Jason Himber (Group Pres Repair cluster) • Matt Crowley (Group Pres Specialty cluster) Neighborly Corporate: • Mike Davis (CEO since July 2024) — linkedin.com/in/mcardavis • Benjamin Lamb (CFO May 2025) • Gagan Sinha (CIO Sept 2025) — ex-Bloomin' Brands • Brad Stevenson (CDO) • Stacy Lynn Bourgeois (CMO) • Grayson Brown (EVP/General Counsel) • Courtney Kolar (CPO) PE: KKR — Felix Gernburd (Partner / Board) Founder: Don Dwyer (1981, original Dwyer Group) | AL4: 🥇 #1 OVERALL TARGET: Gagan Sinha (CIO, joined Sept 2025, Harvard MS Mgmt, ex-Bloomin' Brands CIO) — explicit "shift from primarily building systems in-house to ADOPTING AND INTEGRATING BEST-IN-CLASS PLATFORMS" stance. Mike Davis (CEO, ex-Mathnasium, Atlanta): "So much of being amazing with consumers in today's world is rooted in technology." Felix Gernburd (KKR Board): public quote on "digital transformation in progress." ⚠️ HARD CONFLICT: Smart Fleet USA / Azuga = preferred telematics for ALL 16+ Neighborly brands (NOT GPS Insight). Mike Bidwell passing (Sept 2023) = sensitive context. 👉 See Signal Intel: Neighborly section [v19 Alumni Intel · 05/04/2026]: 3 warm-path/status notes captured. See Col 25 for tactical detail and Signal Intel tab for full roll-up. | AM4: 🎓 NEIGHBORLY EDUCATION CLUSTER (DEEP): TOP LEADERSHIP: • Mike Davis (CEO since July 2024): Pending school confirmation. 13 yrs UMG EVP → CEO Valpak → CEO Mathnasium → Neighborly. Irving TX office. • Jon Shell (CFO, formerly interim CEO): Pending verification • Gagan Sinha (CIO since Sept 2025): Harvard MS Mgmt 2011-2013 ⭐⭐⭐ #1 OVERALL TARGET. Ex-Bloomin' Brands, ex-Inspire Brands. • Brad Stevenson (CDO): Texas A&M College Station BS Kinesiology 1991-1996. MillerCoors career since 1996. • Stacy Lynn Bourgeois (CMO): Northwestern MS Integrated Marketing 2009-2010 + Florida State BA Communications. Ex-Yum Brands, Pizza Hut. • Ben Lamb (CFO May 2025): Baylor BBA Finance/Econ/Intl Business • Courtney Kolar (SVP People Services): Pending school. 9yrs Kohl's HR. GROUP PRESIDENTS: • Matt Crowley (Group Pres-Specialty): USC Marshall MBA. Ex-Valpak EVP. Two decades PE/digital media/Fortune 50. • Jason Himber (Group Pres-Repair: Aire Serv, Glass Doctor, Mr. Electric, Mr. Handyman, Mr. Rooter, Precision, Rainbow): Pending school. 15+ yrs. • Georgeanne Erickson (Group Pres-Maintain: Mr. Appliance, Molly Maid, Window Genie, Mosquito Joe, Five Star Painting, Junk King, Dryer Vent Wizard, Grounds Guys): Pending school. Ex-CMO Fogo de Chão. BRAND PRESIDENTS: • Glenn Lewis (Mr. Appliance): Baylor 1982-1985 + UT Austin 81-82, CFE. Wife Leslie + daughter Calli also Baylor. • Josh McCormick (Mr. Electric): Baylor BBA Mgmt 1999-2002 • Brian Meussner (Mr. Handyman): Central Michigan Univ 1999-2002 • Mike Brickner (Precision Door): Columbia College • Susan McIntosh (Lawn Pride): Cardinal Ritter HS Indianapolis (no college) • Michael Silva-Nash (Molly Maid): U Arkansas Little Rock 2010-2014, International Business + Foreign Language. CFE, bilingual. • Chris Bruno (Window Genie): Tarleton State University BAS Business Admin 2018-2020. CFE. • Evan Brody (Mosquito Joe): Olin School of Business, Washington University in St. Louis ⭐ • Jay Jimenez (Aire Serv NEW Apr 2026): CFE, school pending • Matt Kunz (former Mr. Rooter Pres, NOW LEFT for Fastest Labs CEO Jan 2026): WSU Carson MBA + Northern Illinois BBA + Morrison Tech AS 🎯 BAYLOR CLUSTER: 3 Neighborly leaders (Lewis, McCormick, Lamb) 👉 See Signal Intel tab Master Education Table for sortable view
A5: 2 | B5: AUTHORITY BRANDS | C5: Apax Partners + BCI | D5: P1 #2 · DISPLACEMENT-READY | E5: 12 | F5: 12098 | G5: $181K | H5: Jay Caiafa CEO (joined Aug 2025) Prev: COO Americas, IHG Hotels 4,600 hotels, 26 countries Data/AI focus — new leadership Rob Weddle — OUT (was CEO) | I5: Josh Greear CFO (joined Sept 22, 2025) LinkedIn: linkedin.com/in/joshgreear/ Education: U Richmond BA + Vanderbilt MA ⭐⭐ Atlanta. 4 kids. Prev: CFO Primrose Schools, VP Strategy & BD Cracker Barrel, financial leadership roles The Home Depot. 25+ yrs franchise/finance experience. | J5: Steve Clemente President & COO, Trades | K5: Tij Bedi CTO (joined Aug 2024) ← PRIMARY entry point Tech/FSM mandate angle 9 non-ST brands greenfield Note: Jay Caiafa (CEO) has data + AI background — lead with operational efficiency | N5: Map 9 non-ST brands + Tij Bedi research | O5: Week 1 (research) | P5: GPS: Apax Partners → Charles Layne for PE intro. Tij Bedi is primary tech champion. | Q5: 9 of 12 brands have no ServiceTitan. No displacement. Ryan Bowes = Chief Dev Officer. | R5: Annual Convention — research needed | S5: Unknown | T5: National program likely via Apax Partners — validate FDD Item 8/11 | U5: 🟡 Medium — $2B+ revenue, institutional program almost certain. Tij Bedi (CTO) not the right contact here. | V5: SOURCE: ServiceTitan press release Sep 2024 / public FDD summaries ITEM 11 — Technology: ServiceTitan named as required platform for 3 brands (Benjamin Franklin, Mister Sparky, One Hour) — announced Sep 2024, transition in 2025. 9 remaining brands have NO FSM mandate. PRIOR PLATFORM: Successware (acquired by Authority Brands 2019) — being replaced by ServiceTitan. ✅ GREENFIELD: ASP, Cleaning Authority, DRYmedic, Junkluggers, Lawn Squad, Monster Tree, Mosquito Squad, Screenmobile, STOP Restoration — 9 brands, no mandate. PRIMARY CONTACT: Tij Bedi (CTO, joined Aug 2024) building tech infrastructure. | W5: 📊 USE INSIGHT ENGINE → ROI Calculator tab PRE-POPULATE WITH (9 non-ST greenfield brands only): • Technicians: ~5,000 (9 non-ST brands est.) • Avg Jobs/Tech/Day: 4 • Avg Revenue/Job: $350 • Working Days: 260 PRIMARY AUDIENCE: Tij Bedi (CTO) — use Competitive Matrix tab to show ServiceBridge vs ServiceTitan side by side. Key message: ServiceBridge for the 9 brands ST doesn't serve. No displacement of existing ST mandate. | X5: 68.5 🟡 ACTIVE | Y5: Charles Layne → Apax Partners PE intro path Tij Bedi (CTO Authority Brands) — new hire Aug 2024, direct LinkedIn Andrea Rowan for brand-level account data | Z5: 12/20 60 (mixed — 3 brands ST mandated, 12 brands open) | AA5: 13/15 85 (12,098 techs) | AB5: 12/15 80 (Apax — active investor + co-investor BCI) | AC5: 11/15 70 (Tij Bedi CTO direct, plus parent path) | AD5: 13/15 85 (Jay Caiafa CEO Aug 2025, Josh Greear CFO Sept 2025 — fresh tech direction) | AE5: 7/10 70 (ServiceTitan partial — 12 non-ST brands displaceable) | AF5: 7/10 70 (mix B2B + consumer) | AG5: KEY LINKEDIN URLS (UPDATED v15.34): • Jay Caiafa (CEO Aug 2025): linkedin.com/in/jay-caiafa-65580a1/ USAFA Captain + Duke Law JD + Duke Fuqua MBA ⭐⭐⭐ TRIPLE • Josh Greear (CFO Sept 2025): linkedin.com/in/joshgreear/ U Richmond BA + Vanderbilt MA ⭐⭐ • Steve Clemente (Pres & COO Trades Dec 2025): linkedin.com/in/steve-clemente-trade-brands/ UCF + Webster Master's ⭐⭐ • Ryan Bowes (Chief Growth Officer Feb 2026): linkedin.com/in/ryan-bowes/ Clemson BS+MS Real Estate ⭐ • Tij Bedi (CTO since Aug 2024): linkedin.com/in/tijbedi/ ← PRIMARY tech entry • Stewart Vernon (EVP Emerging Brands): linkedin.com/in/stewart-vernon-asp/ College of Charleston (Macon GA hometown, Stratford Academy) ⭐ • Tom Swift (EVP Outdoor Brands): linkedin.com/in/tom-swift-597a2018/ Presbyterian + Mercer Law + UFlorida LLM Tax + CFP ⭐⭐ • Justin Waltz (Junkluggers Pres): linkedin.com/in/justinwaltz/ • Rob White (Monster Tree Pres): linkedin.com/in/robthewhitewa/ Virginia Tech BS Finance + VCU MBA ⭐ • Farah Bhayani (CLO): SMU BBA + JD ⭐ | AH5: ★ FSM / TECH / DIGITAL TRANSFORMATION QUOTES ★ Tij Bedi (CTO) — Franchising.com BYLINED ARTICLE 2025: "Historically, franchise platforms have grappled with SILOED SYSTEMS across the network and even within each brand. Today, many home service brands are BREAKING DOWN THESE BARRIERS by integrating data from various systems into centralized DATA LAKES. These data-driven decisions enable franchisees to identify trends before they become issues and OPTIMIZE OPERATIONS, improving resource allocation, marketing effectiveness, and customer satisfaction." → DIRECT MATCH for ServiceBridge value prop. He literally wrote the pitch. Reference this article in the LinkedIn DM to him. "As we look to the future, technology will play an increasingly central role in the home service industry." Bedi (Gartner Peer Community): "Better understanding of vision, growth strategy at every level in organization and collaborative decisioning allows empowered and high performing teams contributing to growth and efficiency." | AI5: Authority Brands Annual Convention 🔍 Date/location TBD - research needed Almost certain to exist at $1-2B revenue scale FLDC Atlanta (Oct 6-8, 2026) Caiafa likely C-suite attendee IFA Annual (Feb 2027) 👉 See Event Intelligence tab for full schedule + opportunity analysis | AJ5: ENTRY: Tij Bedi (CTO) tech champion — direct LinkedIn approach appropriate. He just joined to build tech for 9 brands with NO FSM mandate. HOOK: "You just joined to build tech infrastructure for 9 brands with no FSM mandate. ServiceBridge is the fastest path to get there." CHANNEL: 1. LinkedIn to Tij Bedi (direct) 2. Competitive Matrix as conversation starter 3. GPS → Apax Partners intro via Charles (parallel) DISPLACEMENT NOTE: Authority has active ServiceTitan partnership (2024). 9 non-ST brands are greenfield. Caiafa + Greear (CFO Sep 2025) + Clemente are <1yr in role = window open. TIMING: Week 2-3 | AK5: AUTHORITY BRAND-LEVEL ROSTER (UPDATED): Trades Cluster (Steve Clemente): • Benjamin Franklin Plumbing — Steve Clemente direct oversight Punctual Pros multi-unit franchisees: Matt + Aaron Buckwalter (Central PA) Jonathan Marlow (Broad Sky Partners — Punctual Pros backer) Kelley Pendergast (BFP franchisee) Scott Wood Jr. (BFP+OHHAC franchisee Omaha — veteran-supporter) Cory Clinton (BFP GM Indianapolis), Robert Armstrong (Ops Mgr N.Colorado) • One Hour Heating & Air Conditioning — Steve Clemente direct • Mister Sparky Electric — Steve Clemente direct • DRYmedic Restoration — Steve Clemente direct Lindsay Keyser (DRYmedic franchisee feature) • STOP Restoration — Steve Clemente direct Outdoor Cluster (Tom Swift): • Mosquito Squad Plus — Jef Flournoy (Brand Pres, 20yr anniversary brand enhancement) Capricia T. (franchisee feature) • Monster Tree Service — Chris Brown (VP Operations, NEW summer 2024 — former franchisee) • DoodyCalls — Jacob + Susan D'Aniello (Co-Founders) Kara Kelsey (DoodyCalls franchisee feature) • Screenmobile — Clint Rowley (Brand Pres NEW late 2024) • Lawn Squad — Tom Swift oversight, brand pres TBD Emerging Cluster (Stewart Vernon): • ASP — Stewart Vernon (Founder/EVP) • Cleaning Authority — founding brand, corporate-led Shannon Oakley (TCA franchisee Spokane+Bellevue) • Color World Painting — Chris Ring (Brand Pres NEW) Tom Hodgson (Founder 1997) Gary Sheffer (top franchisee Birmingham AL) • Junkluggers — Justin Waltz (Brand Pres Jan 2024) Josh Cohen (Founder, departed) • Homewatch CareGivers — Todd Houghton (Brand Pres) • Woofie's — Amy Addington (President & Co-Founder) Marcie Campagnola (Woofie's franchisee feature) Authority Corporate: • Jay Caiafa (CEO Aug 2025) • Josh Greear (CFO Sept 2025) • Steve Clemente (Pres COO Trades Aug 2025) • Tij Bedi (CTO) • Jordan Wilson (CDO since Jan 2025) • Ryan Bowes (CGTO Feb 2026) • Leanne Stapf (EVP) • Stewart Vernon (EVP Emerging) • Tom Swift (EVP Outdoor) • Adam Terranova (Sr Director Marketing) • Farah ___ (General Counsel May 2025) PE: Apax Partners — Ashish Karandikar (Partner / Board) Former CEOs: Rob Weddle, Craig Donaldson PR: 360PR+ (Vince Powers EVP) + Fish Consulting (Sarah Guffey, Joshua Morris, Brendan Maguire, Nikki Rode) Crisis comms: Kekst CNC (Todd Fogarty) Legal: Foley Lardner (Christina Kennedy) M&A advisor: Boxwood Partners (Brian Alas MD, Patrick Galleher Partner) | AL5: 🥇 PRIMARY: Jay Caiafa (CEO Aug 2025, USAFA Captain + Duke Law JD + Duke Fuqua MBA, 9mo in role, IHG bio "drove innovation through data and AI" across 4,600 hotels). Atlanta. Wife Meredith, 3 sons. Josh Greear (CFO Sept 2025, U Richmond + Vanderbilt, ex-Primrose CFO). 🎯 STRONG: Ryan Bowes (CGTO Feb 2026, Clemson BS+MS, oversees BuyMax GPO platform + franchise dev). Steve Clemente (Pres/COO Trade Brands Dec 2025, ex-Primrose President — oversees Benjamin Franklin, One Hour, Mister Sparky, DRYmedic). ⚠️ ServiceTitan partnership = displacement story, not greenfield. 👉 See Signal Intel: Authority Brands section | AM5: 🎓 AUTHORITY BRANDS EDUCATION CLUSTER (DEEP): EXECUTIVES: • Jay Caiafa (CEO Aug 2025): USAFA Captain + Duke Law JD + Duke Fuqua MBA ⭐⭐⭐ TRIPLE • Josh Greear (CFO Sept 2025): U Richmond BA + Vanderbilt MA. 4 kids, Atlanta. Ex-Cracker Barrel + Home Depot. • Steve Clemente (Pres/COO Trade Brands Dec 2025): UCF BS Liberal Studies + Webster University Master's. 30+ yrs Dick's, Target, Nebraska Book, Primrose Schools President. • Ryan Bowes (CGTO Feb 2026): Clemson BS+MS Real Estate Dev/Finance. Ex-IHG, Marriott, Starwood, FirstKey Homes CIO. • Farah Bhayani (CLO): SMU BBA Real Estate Finance + JD • Stewart Vernon (EVP Emerging Brands, ASP Founder): College of Charleston (corp comms). Macon GA, Stratford Academy. Wife Shannon. • Tom Swift (EVP overseeing Mosquito Squad+Monster Tree+DoodyCalls+Screenmobile, since June 2023): Presbyterian College BA + Mercer Law JD 2001-2003 + UFlorida LLM (Master Tax Law) + CFP. Macon/Bibb County GA. BRAND PRESIDENTS: • Justin Waltz (Junkluggers Pres): Towson University. Started 1-800-GOT-JUNK truck driver 2005. • Rob White (Monster Tree Service Brand Pres Nov 2023): Virginia Tech BS Business Finance + VCU MBA. Ex-Rainbow Restoration Pres. • Todd Houghton (Homewatch CareGivers Pres): Illinois State BS Econ/Business 🎯 DUKE + MACON GA CLUSTER: Caiafa = dual Duke alum. Vernon + Swift both Macon GA roots 👉 See Signal Intel tab Master Education Table for sortable view
