Workbook

Sheet Executive Scorecard
A1: EXECUTIVE SCORECARD · ServiceBridge Franchisor GTM Engagement · April – June 2026
A2: Prepared by Velocity GTM Co LLC · Michael Montgomery Flynt Jr · Metrics auto-update as activity is logged across all tabs
B3: METRIC | D3: TARGET | E3: ACTUAL | F3: % TO GOAL | G3: STATUS
B5: PHASE 1 · 30-DAY · DEVELOP
B6: Target: End of April 2026 · Build the foundation for both tracks
B8: TRACK 1 — FRANCHISOR
B9: Franchisors Profiled (deep research complete) | D9: 9 | E9: =COUNTIF('Track 1 · Franchisors'!D4:D12,"TIER 1")+COUNTIF('Track 1 · Franchisors'!D4:D12,"TIER 2")+COUNTIF('Track 1 · Franchisors'!D4:D12,"TIER 3") -> 0 | F9: =IFERROR(E9/9,0) -> 0 | G9: =IF(E9>=9,"✅ On Track",IF(E9>=9*0.7,"⚠️ At Risk","🔴 Behind")) -> 🔴 Behind
B10: Contacts Mapped (3+ per franchisor = 27 total) | D10: 27 | E10: =0 -> 0 | F10: =IFERROR(E10/27,0) -> 0 | G10: =IF(E10>=27,"✅ On Track",IF(E10>=27*0.7,"⚠️ At Risk","🔴 Behind")) -> 🔴 Behind
B11: Outreach Sequences Live (both tracks active) | D11: 9 | E11: =COUNTIFS('Track 1 · Franchisors'!L4:L12,"Contacted")+COUNTIFS('Track 1 · Franchisors'!L4:L12,"Replied")+COUNTIFS('Track 1 · Franchisors'!L4:L12,"Call Scheduled")+COUNTIFS('Track 1 · Franchisors'!L4:L12,"Discovery Done")+COUNTIFS('Track 1 · Franchisors'!L4:L12,"Proposal Sent")+COUNTIFS('Track 1 · Franchisors'!L4:L12,"Negotiating")+COUNTIFS('Track 1 · Franchisors'!L4:L12,"Pilot Closed") -> 0 | F11: =IFERROR(E11/9,0) -> 0 | G11: =IF(E11>=9,"✅ On Track",IF(E11>=9*0.7,"⚠️ At Risk","🔴 Behind")) -> 🔴 Behind
B12: TRACK 2 — FRANCHISEE
B13: Franchisee Brands Scored (all 85 in database) | D13: 85 | E13: =COUNTA('Track 2 · Franchisees'!B4:B88)-COUNTBLANK('Track 2 · Franchisees'!B4:B88) -> 71 | F13: =IFERROR(E13/85,0) -> 0.83529412 | G13: =IF(E13>=85,"✅ On Track",IF(E13>=85*0.7,"⚠️ At Risk","🔴 Behind")) -> ⚠️ At Risk
B14: Contacts Validated (one per brand) | D14: 85 | E14: =COUNTA('Track 2 · Franchisees'!J4:J88)-COUNTIF('Track 2 · Franchisees'!J4:J88,"(Franchisee Owner)")-COUNTIF('Track 2 · Franchisees'!J4:J88,"(TBD — Research)")-COUNTIF('Track 2 · Franchisees'!J4:J88,"") -> 71 | F14: =IFERROR(E14/85,0) -> 0.83529412 | G14: =IF(E14>=85,"✅ On Track",IF(E14>=85*0.7,"⚠️ At Risk","🔴 Behind")) -> ⚠️ At Risk
B15: Outreach Sequences Live (brands contacted) | D15: 85 | E15: =COUNTIFS('Track 2 · Franchisees'!L4:L88,"Contacted")+COUNTIFS('Track 2 · Franchisees'!L4:L88,"Replied")+COUNTIFS('Track 2 · Franchisees'!L4:L88,"Call Scheduled")+COUNTIFS('Track 2 · Franchisees'!L4:L88,"Discovery Done")+COUNTIFS('Track 2 · Franchisees'!L4:L88,"Proposal Sent")+COUNTIFS('Track 2 · Franchisees'!L4:L88,"Negotiating")+COUNTIFS('Track 2 · Franchisees'!L4:L88,"Pilot Closed") -> 0 | F15: =IFERROR(E15/85,0) -> 0 | G15: =IF(E15>=85,"✅ On Track",IF(E15>=85*0.7,"⚠️ At Risk","🔴 Behind")) -> 🔴 Behind
B16: ENGAGEMENT ACTIVITY — CRM LOG
B17: Total Touchpoints Logged (all channels) | D17: 30 | E17: =COUNTA('Engagement Log'!B5:B80)-COUNTBLANK('Engagement Log'!B5:B80) -> -34 | F17: =IFERROR(E17/30,0) -> -1.1333333 | G17: =IF(E17>=30,"✅ On Track",IF(E17>=30*0.7,"⚠️ At Risk","🔴 Behind")) -> 🔴 Behind
B18: Positive Outcomes (replied, calls, meetings) | D18: 5 | E18: =COUNTIF('Engagement Log'!I5:I80,"Replied – Positive")+COUNTIF('Engagement Log'!I5:I80,"Call Scheduled")+COUNTIF('Engagement Log'!I5:I80,"Call Complete")+COUNTIF('Engagement Log'!I5:I80,"Meeting Complete")+COUNTIF('Engagement Log'!I5:I80,"Pilot Agreed") -> 2 | F18: =IFERROR(E18/5,0) -> 0.4 | G18: =IF(E18>=5,"✅ On Track",IF(E18>=5*0.7,"⚠️ At Risk","🔴 Behind")) -> 🔴 Behind
B20: PHASE 2 · 60-DAY · ENGAGE
B21: Target: End of May 2026 · Drive active conversations on both tracks
B23: TRACK 1 — FRANCHISOR
B24: Franchisors in Active Conversation | D24: 3 | E24: =COUNTIFS('Track 1 · Franchisors'!L4:L12,"Discovery Done")+COUNTIFS('Track 1 · Franchisors'!L4:L12,"Proposal Sent")+COUNTIFS('Track 1 · Franchisors'!L4:L12,"Negotiating")+COUNTIFS('Track 1 · Franchisors'!L4:L12,"Pilot Closed") -> 0 | F24: =IFERROR(E24/3,0) -> 0 | G24: =IF(E24>=3,"✅ On Track",IF(E24>=3*0.7,"⚠️ At Risk","🔴 Behind")) -> 🔴 Behind
B25: Mandate Validated (confirmed at franchisor level) | D25: 3 req. | E25: =0 -> 0 | F25: — | G25: Manual
B26: Franchisor Discovery Calls Completed | D26: 3 | E26: =COUNTIF('Engagement Log'!H5:H80,"Discovery Call") -> 2 | F26: =IFERROR(E26/3,0) -> 0.66666667 | G26: =IF(E26>=3,"✅ On Track",IF(E26>=3*0.7,"⚠️ At Risk","🔴 Behind")) -> 🔴 Behind
B27: Proposals / ROI Models Submitted | D27: 1 | E27: =COUNTIFS('Track 1 · Franchisors'!L4:L12,"Proposal Sent")+COUNTIFS('Track 1 · Franchisors'!L4:L12,"Negotiating") -> 0 | F27: =IFERROR(E27/1,0) -> 0 | G27: =IF(E27>=1,"✅ On Track",IF(E27>=1*0.7,"⚠️ At Risk","🔴 Behind")) -> 🔴 Behind
B28: TRACK 2 — FRANCHISEE
B29: Franchisees Engaged (in active conversation) | D29: 25 | E29: =COUNTIFS('Track 2 · Franchisees'!L4:L88,"Replied")+COUNTIFS('Track 2 · Franchisees'!L4:L88,"Call Scheduled")+COUNTIFS('Track 2 · Franchisees'!L4:L88,"Discovery Done")+COUNTIFS('Track 2 · Franchisees'!L4:L88,"Proposal Sent")+COUNTIFS('Track 2 · Franchisees'!L4:L88,"Negotiating")+COUNTIFS('Track 2 · Franchisees'!L4:L88,"Pilot Closed") -> 0 | F29: =IFERROR(E29/25,0) -> 0 | G29: =IF(E29>=25,"✅ On Track",IF(E29>=25*0.7,"⚠️ At Risk","🔴 Behind")) -> 🔴 Behind
B30: Confirmed Next Steps (committed to follow-up) | D30: 10 | E30: =COUNTIFS('Track 2 · Franchisees'!L4:L88,"Call Scheduled")+COUNTIFS('Track 2 · Franchisees'!L4:L88,"Discovery Done")+COUNTIFS('Track 2 · Franchisees'!L4:L88,"Proposal Sent")+COUNTIFS('Track 2 · Franchisees'!L4:L88,"Negotiating")+COUNTIFS('Track 2 · Franchisees'!L4:L88,"Pilot Closed") -> 0 | F30: =IFERROR(E30/10,0) -> 0 | G30: =IF(E30>=10,"✅ On Track",IF(E30>=10*0.7,"⚠️ At Risk","🔴 Behind")) -> 🔴 Behind
B31: Pilots Seeded (pilot conversation started) | D31: 3–5 | E31: =COUNTIFS('Track 2 · Franchisees'!L4:L88,"Proposal Sent")+COUNTIFS('Track 2 · Franchisees'!L4:L88,"Negotiating")+COUNTIFS('Track 2 · Franchisees'!L4:L88,"Pilot Closed") -> 0 | F31: — | G31: Manual
B32: HIGH Pilot Potential Accounts Contacted | D32: 15 | E32: =COUNTIFS('Track 2 · Franchisees'!I4:I88,"HIGH",'Track 2 · Franchisees'!L4:L88,"Contacted")+COUNTIFS('Track 2 · Franchisees'!I4:I88,"HIGH",'Track 2 · Franchisees'!L4:L88,"Replied")+COUNTIFS('Track 2 · Franchisees'!I4:I88,"HIGH",'Track 2 · Franchisees'!L4:L88,"Call Scheduled")+COUNTIFS('Track 2 · Franchisees'!I4:I88,"HIGH",'Track 2 · Franchisees'!L4:L88,"Discovery Done")+COUNTIFS('Track 2 · Franchisees'!I4:I88,"HIGH",'Track 2 · Franchisees'!L4:L88,"Proposal Sent")+COUNTIFS('Track 2 · Franchisees'!I4:I88,"HIGH",'Track 2 · Franchisees'!L4:L88,"Pilot Closed") -> 0 | F32: =IFERROR(E32/15,0) -> 0 | G32: =IF(E32>=15,"✅ On Track",IF(E32>=15*0.7,"⚠️ At Risk","🔴 Behind")) -> 🔴 Behind
B34: PHASE 3 · 90-DAY · CLOSE
B35: Target: End of June 2026 · Close pilots, advance franchisors, deliver playbook
B37: TRACK 1 — FRANCHISOR
B38: Franchisor in Qualified Interest Discussion | D38: 1+ req. | E38: =COUNTIFS('Track 1 · Franchisors'!L4:L12,"Negotiating")+COUNTIFS('Track 1 · Franchisors'!L4:L12,"Pilot Closed") -> 0 | F38: — | G38: Manual
B39: Franchisor Deal in Progress / Closed | D39: 1 | E39: =COUNTIFS('Track 1 · Franchisors'!L4:L12,"Pilot Closed") -> 0 | F39: =IFERROR(E39/1,0) -> 0 | G39: =IF(E39>=1,"✅ On Track",IF(E39>=1*0.7,"⚠️ At Risk","🔴 Behind")) -> 🔴 Behind
B40: PE Warm Intros Activated (Charles path) | D40: Manual | E40: =0 -> 0 | F40: — | G40: Manual
B41: GTM Playbook Delivered | D41: Yes/No | E41: No | F41: — | G41: Manual
B42: TRACK 2 — FRANCHISEE
B43: Pilots Closed (signed agreements) | D43: 2 | E43: =COUNTIFS('Track 2 · Franchisees'!L4:L88,"Pilot Closed") -> 0 | F43: =IFERROR(E43/2,0) -> 0 | G43: =IF(E43>=2,"✅ On Track",IF(E43>=2*0.7,"⚠️ At Risk","🔴 Behind")) -> 🔴 Behind
B44: Pilots in Active Negotiation | D44: 3 | E44: =COUNTIFS('Track 2 · Franchisees'!L4:L88,"Negotiating") -> 0 | F44: =IFERROR(E44/3,0) -> 0 | G44: =IF(E44>=3,"✅ On Track",IF(E44>=3*0.7,"⚠️ At Risk","🔴 Behind")) -> 🔴 Behind
B45: Total Pipeline Value Created (Closed + Negotiating) | D45: $50K+ | E45: =0 -> 0 | F45: — | G45: Manual
B46: Extension Plan Presented to Core Team | D46: Yes/No | E46: No | F46: — | G46: Manual
...

Sheet Changelog v15.6
A1: CRM v15.6 — Validation Changelog
A2: Validated April 29, 2026 by Velocity GTM Co LLC. 9 changes applied to Track 2 · Franchisees sheet.
A4: Date | B4: Row | C4: Brand | D4: Field Changed | E4: Old Value | F4: New Value | G4: Reason for Change
A5: 2026-04-29 20:24 | B5: 40 | C5: USA Insulation | D5: FSM Status | E5: Greenfield | F5: At-Risk SB | G5: Per Andrea Apr 2026: 75% SB penetration but transitioning OFF over next year. Not greenfield — retention/monitor play.
A6: 2026-04-29 20:24 | B6: 40 | C6: USA Insulation | D6: Current FSM Platform | E6: Greenfield / Paper | F6: ServiceBridge (75%, AT-RISK — transitioning off per Andrea Apr 2026) | G6: Andrea confirmed Apr 2026: USA Insulation transitioning off ServiceBridge over the next year. Not greenfield.
A7: 2026-04-29 20:24 | B7: 40 | C7: USA Insulation | D7: Notes | E7: Seasonal scheduling — strong dispatch fit | F7: ⚠️ AT-RISK / RETENTION PLAY — Andrea confirmed Apr 2026: USA Insulation transitioning off ServiceBridge over next year. Posture: dual-track — defend if reversible, reset relationship at brand-corp lev | G7: Added retention-play context per Threshold P2 readiness package.
A8: 2026-04-29 20:24 | B8: 40 | C8: USA Insulation | D8: Combined Score | E8: 84 🟡 QUEUE | F8: 84* ⚠️ RECALIBRATE — at-risk, not greenfield | G8: Score derived from greenfield assumption that does not apply. Flagged for recalibration.
A9: 2026-04-29 20:24 | B9: 37 | C9: BELFOR Property Restoration | D9: FSM Status | E9: Greenfield | F9: Not FSM Scope | G9: BELFOR Property Restoration is the parent restoration business — runs on restoration management software (Xactimate/Symbility), not FSM. Out of ServiceBridge category.
A10: 2026-04-29 20:24 | B10: 37 | C10: BELFOR Property Restoration | D10: Current FSM Platform | E10: Greenfield / Paper | F10: Restoration management software (Xactimate/Symbility ecosystem) — not FSM category | G10: Restoration management is a different software category. Not displaceable by FSM.
A11: 2026-04-29 20:24 | B11: 37 | C11: BELFOR Property Restoration | D11: Combined Score | E11: 116 🔴 LEAD PILOT | F11: EXCLUDE ⛔ NOT FSM SCOPE | G11: Excluded from FSM engagement. Score was based on incorrect greenfield framework.
A12: 2026-04-29 20:24 | B12: 37 | C12: BELFOR Property Restoration | D12: Notes | E12: Large restoration crews — documentation + compliance | F12: ⛔ EXCLUDED — different software ecosystem (restoration management). Engage at parent franchisor level (BELFOR FG) only, not as Stage 2 brand-corp target. | Large restoration crews — documentation + co | G12: Added exclusion rationale.
A13: 2026-04-29 20:24 | B13: 2 | C13: (Header) | D13: Subheader version stamp | E13: Velocity GTM Co LLC · Sorted by parent franchisor · GPS Insight warm accounts highlighted · Pilot potential scored HIGH / MED / LOW | F13: Velocity GTM Co LLC · Sorted by parent franchisor · GPS Insight warm accounts prioritized · v15.6 — validated April 29, 2026 | G13: Version bump and validation date.
A16: Validation Summary
A17: ✓ Total brands in Track 2 reviewed: 78
A18: ✓ Portfolio assignments verified — CRM is correct (no misassignments found)
A19: ✓ Score-FSM consistency check passed — no logic errors
A20: ✓ No duplicate brand entries
A21: ✓ All 78 brands have parent franchisor, trade, location, FSM status fields populated
A22: ⚠️ 64 of 78 brands marked "Validate with Andrea" for GPSI customer overlap — REQUIRES GPSI team query
A23: ⚠️ ~68 of 78 brands have "TBD" for Owner/Decision Maker — REQUIRES Andrea/Marketing team intel
A24: ⚠️ 2 substantive corrections applied: USA Insulation (At-Risk, not Greenfield) + BELFOR Property Restoration (Not FSM scope)
A26: NEXT STEPS for full data closure:
A27: 1. GPSI customer database query for all 78 brands → fills GPSI Customer column + Telematics column
A28: 2. Brand-corp leadership intel from Andrea/Marketing team → fills Owner/DM column for ~68 brands
... A32: Track 1 · Franchisors V2 Realignment (April 29, 2026)
A33: 2026-04-29 | B33: 4-14 | C33: NEIGHBORLY | D33: V2 Track 1 position | E33: 9 | F33: 1 | G33: V2 ranking
A34: 2026-04-29 | B34: 4-14 | C34: NEIGHBORLY | D34: TIER label | E34: TIER 3 | F34: P1 #1 · PE-GATED | G34: V2 character label
A35: 2026-04-29 | B35: 4-14 | C35: NEIGHBORLY | D35: FRANCHISOR SCORE | E35: 39 ⚪ BUILD | F35: 76.5 🔴 PE-GATED — DO NOT APPROACH DIRECT | G35: V2 score (greenfield-weighted)
A36: 2026-04-29 | B36: 4-14 | C36: AUTHORITY BRANDS | D36: V2 Track 1 position | E36: 8 | F36: 2 | G36: V2 ranking
A37: 2026-04-29 | B37: 4-14 | C37: AUTHORITY BRANDS | D37: TIER label | E37: TIER 3 | F37: P1 #2 · DISPLACEMENT-READY | G37: V2 character label
A38: 2026-04-29 | B38: 4-14 | C38: AUTHORITY BRANDS | D38: FRANCHISOR SCORE | E38: 61 🟡 ACTIVE | F38: 68.5 🟡 ACTIVE | G38: V2 score (greenfield-weighted)
A39: 2026-04-29 | B39: 4-14 | C39: EMPOWER BRANDS | D39: V2 Track 1 position | E39: 3 | F39: 3 | G39: V2 ranking
A40: 2026-04-29 | B40: 4-14 | C40: EMPOWER BRANDS | D40: TIER label | E40: TIER 1 | F40: P1 #3 · GREENFIELD-LED | G40: V2 character label
A41: 2026-04-29 | B41: 4-14 | C41: EMPOWER BRANDS | D41: FRANCHISOR SCORE | E41: 60 🟡 ACTIVE | F41: 66.2 🟡 ACTIVE | G41: V2 score (greenfield-weighted)
A42: 2026-04-29 | B42: 4-14 | C42: RESIBRANDS | D42: V2 Track 1 position | E42: 5 | F42: 4 | G42: V2 ranking
A43: 2026-04-29 | B43: 4-14 | C43: RESIBRANDS | D43: TIER label | E43: TIER 2 | F43: P1 #4 · FAST-CYCLE | G43: V2 character label
A44: 2026-04-29 | B44: 4-14 | C44: RESIBRANDS | D44: FRANCHISOR SCORE | E44: 58 🟡 ACTIVE | F44: 60.2 🟢 ACTIVE | G44: V2 score (greenfield-weighted)
... A60: 2026-04-29 | B60: 4-14 | C60: THRESHOLD | D60: FRANCHISOR SCORE | E60: 73 🔴 MOVE NOW | F60: P2 SET | G60: P2 set qualitatively classified
A62: Other CRM Tabs V2 Realignment (April 29, 2026)
A63: 2026-04-29 | B63: 💡 Engagement Ideas | C63: BELFOR | D63: Priority cell | E63: 🔴 #1 | F63: 🟡 P2 DE-FACTO ANCHOR — HOODZ + DUCTZ at 94% SB; convert to mandate | G63: V2 ranking realignment — was old framework priority, now V2 character label.
...

Sheet PE Relationship Map
A1: PE RELATIONSHIP MAP · GPS Insight Warm Introduction Paths · ServiceBridge GTM Engagement
A2: Velocity GTM Co LLC · These introductions require GPS Insight coordination · Every row is a GPS Insight ask tracked to completion
A3: 🔑 Each row on this tab represents an introduction path that runs through GPS Insight's PE network · Status updated as introductions progress
B5: WHY THIS TAB EXISTS
B6: A warm PE-level introduction compresses a 6-month enterprise sales cycle to 6 weeks. Accel-KKR (GPS Insight's backer) has portfolio relationships, co-investment networks, and operating partner connections that give you an immediate credibility bridge to the PE firms backing your 9 priority franchisor accounts. None of these introductions happen without Charles Layne. This tab tracks every PE relationship, who at GPS Insight owns it, what the ask is, and where the introduction stands.
B8: PE FIRM | C8: FUND TYPE & AUM | D8: PORTFOLIO COMPANY | E8: GPS INSIGHT OWNER | F8: PE TARGET CONTACT (Named Individuals) | G8: INTRO PATH | H8: PRIORITY | I8: INTRO STATUS | J8: LAST GPS ACTION | K8: NEXT GPS ACTION NEEDED | L8: NEXT DATE | M8: NOTES / INTELLIGENCE | N8: PE DEAL TEAM FOCAL POINTS ← Researched contacts
B10: SECTION 1 · ACCEL-KKR NETWORK · GPS Insight's Own PE Backer · Highest Leverage
B11: Accel-KKR backed GPS Insight. This is your warmest possible intro path. Charles Layne has direct relationships with the AKKR deal team.
B13: Accel-KKR | C13: Tech-Focused PE ~$10B+ AUM | D13: GPS Insight / ServiceBridge (Portfolio Company) | E13: GPS Insight (Charles Layne, CEO) | F13: Accel-KKR Internal (GPS Insight board-level) | G13: Charles Layne → AKKR deal team → PE portfolio introductions | H13: 🔴 Critical | I13: Not Started | K13: 📞 On me — calling Charles. Asking GPS Insight to brief AKKR and open intro paths to the four PE firms. | L13: Week 1 | M13: GPS Insight backer. Charles Layne has direct AKKR deal team relationships. This single conversation unlocks all downstream PE intros. | N13: TBD — Accel-KKR deal team partner for GPS Insight ← Charles Layne is the direct relationship Accel-KKR = GPS Insight's own PE backer — highest leverage intro chain
B14: KKR | C14: Large-Cap PE $349B+ AUM | D14: Neighborly (16 brands, 13,259 techs) | E14: GPS Insight (Charles Layne, CEO) | F14: Felix Gernburd Managing Director, KKR Led Neighborly acquisition 2021 North American PE fund | G14: Charles → Accel-KKR deal team → KKR deal team → Felix Gernburd | H14: 🔴 Critical | I14: Not Started | K14: Flag to Charles that the Accel-KKR → KKR path is the play for Neighborly. Ask him to request a warm intro to Felix Gernburd — KKR Partner, Neighborly board seat. | L14: Week 1 | M14: KKR acquired Neighborly (Jul 2021) from Harvest Partners. Felix Gernburd is on Neighborly board. ST renewal window 2025–2027. One KKR-level conversation positions us for that window. | N14: Felix Gernburd — Managing Director, KKR Named in KKR/Neighborly acquisition press release as deal lead Intro path: Charles Layne → Accel-KKR → KKR → Felix Gernburd ⚠️ DO NOT cold outreach — PE intro only
B16: SECTION 2 · TIER 1 FRANCHISOR PE BACKERS · Active Introduction Requests
B17: These PE firms back your Tier 1 accounts. A single intro at the PE level is worth months of direct franchisor outreach.
B19: American Securities | C19: Mid-Market PE ~$10B AUM | D19: BELFOR Franchise Group (14 brands, 9,250 techs) | E19: GPS Insight (Charles Layne, CEO) | F19: David Horing Co-Chair Investment Committee Director, BELFOR (since 1995) Managing Member, active funds Ryan Nolan Director, BELFOR Joined 2017, ex-JPMorgan David Musicant Director, BELFOR Joined 2011, deal sourcing Ex-BofA/Merrill Lynch MD Loren Easton Chairman, BELFOR board | G19: Charles → AKKR deal team → American Securities operating partners | H19: 🔴 Critical | I19: Not Started | K19: Week 1 — Charles Layne call. Ask him to surface any AKKR → American Securities relationship. American Securities has board representation at BELFOR — an operating partner intro skips directly to the mandate decision. | L19: Week 1 | M19: American Securities board is active on ops improvement at BELFOR. Tech standardization directly supports their portfolio thesis. BELFOR sold 30 new franchise territories Dec 2024 — mandate now = every new franchisee is a guaranteed adoption. | N19: PRIMARY: David Horing (Co-Chair IC, Director BELFOR since 1995) OPERATIONAL: Ryan Nolan (Director BELFOR, joined 2017, ex-JPMorgan) RELATIONSHIPS: David Musicant (Director BELFOR, deal sourcing/capital markets) CHAIRMAN: Loren Easton (BELFOR board chairman) INTRO PATH: Charles Layne → Accel-KKR → American Securities Source: american-securities.com team pages (confirmed)
B20: The Riverside Company | C20: Global Mid-Market PE $13B+ AUM | D20: Threshold Brands (10 brands, 6,250 techs) | E20: GPS Insight (Charles Layne, CEO) | F20: Loren Schlachet Managing Partner, Riverside Leads Threshold platform Brian Sauer Senior Partner, Riverside Named on Threshold press releases Steve Rice Principal Caroline Quoyeser Assistant Vice President Deniz Oran Associate Tom Silk Operating Partner Chrissie Yim Finance Director | G20: Charles → AKKR deal team → Riverside Company LP or operating partner relationship | H20: 🟡 High | I20: Not Started | K20: Once the AKKR brief is confirmed, ask Charles to surface any Riverside connection through the PE network. Riverside is approaching exit window — technology standardization improves the EBITDA multiple. | L20: Week 2 | M20: Threshold is Riverside's home services platform (formed 2021). Glassdoor shows high turnover and EBITDA pressure from Riverside. LP-reportable tech standardization is the pitch to the PE firm, not to Hagan Kappler. | N20: PRIMARY: Loren Schlachet (Managing Partner — leads Threshold platform) DEAL LEAD: Brian Sauer (Senior Partner — named on all Threshold add-on releases) OPERATIONAL: Steve Rice (Principal) + Caroline Quoyeser (AVP) + Deniz Oran (Associate) FINANCE: Chrissie Yim (Finance Director) SOURCING: Jeremy Holland (Partner) + Connor McLaughlin (VP Origination) Source: Riverside press release — Miracle Method add-on (Dec 2023)
B21: MidOcean Partners | C21: Mid-Market PE $6B+ AUM | D21: Empower Brands (10 brands, 5,150 techs) | E21: GPS Insight (Charles Layne, CEO) | F21: Eric Roth Principal/Partner, MidOcean Covers Empower Brands Christopher M. Grandpre Operating Partner, MidOcean Chairman, Empower Brands 30+ yrs franchise M&A Founded Outdoor Living Brands 2008 | G21: Charles → AKKR deal team → MidOcean operating partner | H21: 🟡 High | I21: Not Started | K21: Ask Charles about MidOcean connection through Charles / AKKR. MidOcean invested in Empower Dec 2020 — approaching exit window. EBITDA improvement before exit is the story. | L21: Week 2 | M21: MidOcean invested in Empower Brands Dec 2020. Typical hold 5–7 years puts exit window at 2025–2027. First-mover FSM standardization documented before exit = multiple expansion story for MidOcean LPs. | N21: PRIMARY: Eric Roth (covers Empower Brands at MidOcean — confirmed on MidOcean website) OPERATING: Christopher M. Grandpre (Operating Partner + Chairman of Empower Brands) → Founded Outdoor Living Brands 2008 (precursor to Empower) → 30+ years franchise M&A / investment banking INTRO PATH: Charles Layne → MidOcean → Eric Roth or Grandpre Source: midoceanpartners.com + The Joint Corp. press release (May 2025)
B23: SECTION 3 · TIER 2 FRANCHISOR PE BACKERS · Build Relationships in Parallel
B24: Smaller or founder-backed platforms. PE path may be lighter — but still surface any connections through Charles before going cold.
B26: Susquehanna Private Capital | C26: Growth Equity (Susquehanna Int'l Group) | D26: Premium Service Brands (8 brands, 4,950 techs) | E26: GPS Insight (Charles Layne, CEO) | F26: Kyle Squillario Co-Head, Susquehanna Private Capital Named in PSB deal announcement SPC Team: 7 people total 2 Partners, 5 Principals Bala Cynwyd PA | G26: Charles → AKKR → Susquehanna Private Capital connection (if any) | H26: 🔵 Medium | I26: Not Started | K26: Check with Charles if AKKR has any Susquehanna / SGE connection. If not, direct approach to Paul Flick (CEO) is the primary path — SGE is growth equity, not traditional PE, so the founder is the decision-maker. | L26: Week 2 | M26: Susquehanna Private Capital is the investment arm of Susquehanna International Group. PSB is founder-led with PE backing — Paul Flick still runs the business. Direct CEO outreach is the backup if PE path yields nothing. | N26: PRIMARY: Kyle Squillario (Co-Head, SPC — quoted in PSB press release 2021) FIRM: Susquehanna Private Capital — funded by founders of Susquehanna Int'l Group SPC SIZE: ~7 person team, 2 partners — small firm, direct access INTRO: Charles Layne → SPC → Kyle Squillario Source: BusinessWire PSB/SPC announcement (March 2021)
B27: Princeton Equity Group | C27: Franchise-Focused PE Franchise-only investor | D27: Five Star Franchising (5 brands, 2,350 techs) | E27: GPS Insight (Charles Layne, CEO) | F27: Derek DeBenedetto Princeton Equity Group Email: derek@princetonequity.com IFA/conference meeting contact Paul Kuppich Partner (joined 2025) Capital formation focus | G27: Charles → AKKR → Princeton Equity (franchise-focused PE — likely known in network) | H27: 🔵 Medium | I27: Not Started | K27: Week 2 — Princeton Equity exclusively invests in franchise companies — very tight network. Ask Charles if AKKR has any Princeton connection. Year 5 of investment means exit pressure building. | L27: Week 2 | M27: Princeton Equity Group exclusively invests in franchisors and multi-unit companies. Five Star is in Year 5 (invested Jun 2021). EBITDA improvement documented now = higher exit multiple for Princeton. Scott Abbott (CEO) is founder — direct outreach is solid backup. | N27: MEETING CONTACT: Derek DeBenedetto (derek@princetonequity.com) → Listed as IFA 2026 meeting contact in Princeton Year in Review PARTNER: Paul Kuppich (joined 2025 — capital formation + investor relations) FIRM CONTEXT: Princeton invested 2021, Five Star in Year 5 — exit window approaching → ~$350M deployed 2025 across 3 new platforms INTRO PATH: Charles Layne → Princeton Equity → Derek DeBenedetto Source: Princeton 2025 Year in Review + LinkedIn announcement
B28: Dudan Group | C28: Family Office (Founder Capital) | D28: HomeFront Brands (5 brands, 2,550 techs) | E28: GPS Insight (Charles Layne, CEO) | F28: Jeff Dudan Chairman & CEO, HomeFront Founder, Dudan Group Forbes contributor, podcaster Zack Dudan CGO, HomeFront Brands Family office — no external PE team | G28: Direct — Jeff Dudan is both the PE backer AND the CEO. No intermediary needed. | H28: ⚪ Low | I28: Not Started | K28: NO GPS INTRO NEEDED: Jeff Dudan controls both the capital and the operating company. Approach directly. This is the one account where PE intro is not the accelerant — the CEO relationship is. | L28: Week 2 | M28: Dudan Group is Jeff Dudan's family office. He is Chairman + CEO. Direct LinkedIn / podcast outreach to Jeff is faster than any PE path. Note for Charles: no intro needed here. | N28: FAMILY OFFICE: Dudan Group = Jeff Dudan's personal capital — no external PE team DIRECT APPROACH: Jeff Dudan is both PE backer AND operating CEO → Forbes contributor, podcaster — content/thought leadership angle OPERATIONAL: Zack Dudan (CGO) = franchise operations + Homecoming vendor path NO PE INTRO NEEDED — direct approach is the right path Source: HomeFront public filings + Forbes contributor profile
B30: SECTION 4 · TIER 3 FRANCHISOR PE BACKERS · Long Cycle · Relationship Play
B31: Authority Brands and Neighborly have large PE backers. The cycle is long — but the deal size is enormous. Build the relationship now.
B33: Apax Partners + BCI | C33: Large-Cap PE Apax $60B+ · BCI C$211B | D33: Authority Brands (12 brands, 12,098 techs) | E33: GPS Insight (Charles Layne, CEO) | F33: Ashish Karandikar Partner, Apax Partners Led Authority Brands acquisition 2018 Quoted in deal press release BCI (minority stake 2022) British Columbia Investment Mgmt Corp | G33: Charles → AKKR deal team → Apax Partners relationship (LP or co-invest level) | H33: 🟡 High | I33: Not Started | K33: WEEK 1 (research): Ask Charles if AKKR has any LP overlap with Apax fund. Apax explicitly cited 'digitalization' as the AB investment thesis — that is ServiceBridge's positioning. BCI co-invested Sep 2022. | L33: Week 1 (research) | M33: Apax acquired Authority Brands Sep 2017. BCI co-invested Sep 2022 for 'technology transformation.' Apax partner Ashish Karandikar led the deal. Tij Bedi (CTO) was hired Aug 2024 — the tech agenda is active. A PE-level intro to Apax gets us to Tij Bedi much faster. | N33: APAX LEAD: Ashish Karandikar (Partner, Apax — quoted as deal lead in 2018 acquisition) → 'We have been attracted to the home services market for some time' BCI: British Columbia Investment Management Corp (significant minority stake, Sep 2022) → Largest institutional investor in Canada INTRO PATH: Charles Layne → Apax → Ashish Karandikar NOTE: Apax-focused on digitisation/tech for Authority — CTO Tij Bedi (Aug 2024) is the signal Source: Apax.com + PRNewswire acquisition announcement (Sep 2018)
B34: KKR (Neighborly) | C34: Already covered in Section 1 $349B+ AUM | D34: Neighborly (16 brands, 13,259 techs) | E34: GPS Insight (Charles Layne, CEO) | F34: Felix Gernburd Managing Director, KKR Led Neighborly acquisition 2021 ⚠️ DO NOT approach direct | G34: See Section 1 — same KKR path. Do not duplicate effort. | H34: 🔴 Critical | I34: Not Started | K34: ↑ Same KKR path as Section 1 — no separate ask needed. Tracking there. | L34: Week 1 | M34: Neighborly is tracked in Section 1 under the KKR relationship. This row is a reminder that Neighborly PE path and Authority Brands PE path are separate KKR / Apax conversations. | N34: Same as Section 1 — Felix Gernburd is the KKR Neighborly contact ⚠️ DO NOT approach direct under any circumstances INTRO PATH ONLY: Charles Layne → Accel-KKR → KKR → Felix Gernburd Source: KKR/Neighborly acquisition press release BusinessWire (July 2021)
B36: GPS INSIGHT ACTION SUMMARY · The Specific Asks for Charles Layne by Week
B38: WEEK | C38: GPS CONTACT | E38: THE ASK | I38: FOR ACCOUNT | K38: URGENCY | L38: STATUS
B39: Week 1 | C39: GPS Insight (Charles Layne, CEO) | E39: Brief the Accel-KKR deal team on the ServiceBridge GTM initiative. Need AKKR to facilitate PE-level introductions to American Securities (BELFOR), Riverside (Threshold), MidOcean (Empower), and KKR (Neighborly). | I39: ALL 9 FRANCHISORS | K39: 🔴 Critical | L39: Not Started
B40: Week 1 | C40: GPS Insight (Charles Layne, CEO) | E40: Specific KKR ask: Ask for Accel-KKR → KKR deal team intro to Felix Gernburd (KKR Partner / Neighborly Board). One call at the KKR level positions ServiceBridge for the Neighborly ST contract renewal window 2025–2027. | I40: NEIGHBORLY | K40: 🔴 Critical | L40: Not Started
B41: Week 1 | C41: GPS Insight (Garrett Else, CFO) | E41: Schedule 30-minute session to walk through the Insight Engine ROI model assumptions. Garrett's sign-off validates the financial narrative before we take it external to any PE operating partner or franchisor CFO. | I41: ALL ACCOUNTS (ROI Model) | K41: 🔴 Critical | L41: Not Started
B42: Week 1 | C42: GPS Insight (Andrea Rowan, GM) | E42: Connect Mike Flynt with Angie (GPS Insight data strategist) to obtain the micro-franchise company list. This expands Track 2 pipeline beyond the current 85-brand database. | I42: TRACK 2 FRANCHISEE | K42: 🟡 High | L42: Not Started
B43: Week 1 | C43: GPS Insight (Andrea Rowan, GM) | E43: Get the GPS Insight existing telematics client list for cross-referencing against all 9 franchisor accounts. Required conflict check before any outreach begins. | I43: ALL 9 FRANCHISORS | K43: 🔴 Critical | L43: Not Started
B44: Week 2 | C44: GPS Insight (Charles Layne, CEO) | E44: Follow-up on AKKR intro request. Confirm which PE firms have responded and whether any calls are scheduled. If American Securities intro is confirmed, brief Mike before the call. | I44: BELFOR American Securities | K44: 🟡 High | L44: Not Started
B45: Week 2 | C45: GPS Insight (Charles Layne, CEO) | E45: 🔍 On me to check whether there's any Apax Partners (Authority Brands backer) connection through AKKR LP network or co-investment relationships. Apax cited 'digitalization' as their Authority Brands investment thesis — perfect alignment. | I45: AUTHORITY BRANDS Apax Partners | K45: 🟡 High | L45: Not Started
B46: Week 3 | C46: GPS Insight (Garrett Else, CFO) | E46: ROI model sign-off — confirm which assumptions are cleared for external use. Garrett's endorsement as GPS Insight CFO is the credibility layer when the model goes in front of a PE operating partner or franchisor CFO. | I46: ALL ACCOUNTS (ROI Model) | K46: 🔴 Critical | L46: Not Started
B47: Week 4 | C47: GPS Insight (Charles Layne, CEO) | E47: 30-Day check-in: Where do the PE intro paths stand? Which firms have responded? Is a KKR / Felix Gernburd call on the calendar? Any additional PE relationships to activate in Month 2? | I47: ALL PE PATHS | K47: 🟡 High | L47: Not Started
B48: Month 2 | C48: GPS Insight (Charles Layne, CEO) | E48: If Accel-KKR intro has not yet produced a franchisor meeting: ask Charles to make a direct personal call to the PE operating partner. His personal relationship is the accelerant — not a formal intro request. | I48: STALLED ACCOUNTS | K48: 🔵 Medium | L48: Not Started
A50: Prepared by Velocity GTM Co LLC on behalf of GPS Insight / ServiceBridge · Michael Montgomery Flynt Jr · 919.434.6720 · mflyntjr@gmail.com · Confidential · April 2026

Sheet Track 1 · Franchisors
A1: TOP FRANCHISOR ACCOUNTS · Track 1 (P1 ×7) + P2 Set (×3) · V2 Greenfield-Weighted Ranking
A2: Velocity GTM Co LLC · GPS Insight / ServiceBridge Engagement · V2 Ranking April 28, 2026 · CRM v15.6 — validated April 29, 2026
A3: # | B3: FRANCHISOR | C3: PE BACKER | D3: TIER | E3: BRANDS | F3: TECHS | G3: ARR EST. | H3: CEO | I3: CFO | J3: COO / PRESIDENT | K3: BD / FRANCHISE DEV | L3: ENGAGEMENT STATUS | M3: LAST CONTACT | N3: NEXT STEP | O3: NEXT DATE | P3: GPS INSIGHT SUPPORT | Q3: NOTES | R3: ANNUAL CONVENTION | S3: VENDORS / PARTNERS INVITED? | T3: INSURANCE PROGRAM / CARRIER | U3: INSURANCE GTM ANGLE | V3: FDD INTEL (Items 8·11·19) | W3: INSIGHT ENGINE INPUTS ← Pre-populate ROI Calc | X3: FRANCHISOR SCORE / 100 | Y3: GPS INSIGHT EXEC CONTACT ← Internal intro path | Z3: GREENFIELD SCORE (V2 · 20%) | AA3: NETWORK SCORE (V2 · 15%) | AB3: PE SCORE (V2 · 15%) | AC3: DM ACCESS SCORE (V2 · 15%) | AD3: URGENCY SCORE (V2 · 15%) | AE3: DISPLACEMENT SCORE (V2 · 10%) | AF3: C/B MIX SCORE (V2 · 10%)
A4: 1 | B4: NEIGHBORLY | C4: KKR ($349B+ AUM) | D4: P1 #1 · PE-GATED | E4: 16 | F4: 13259 | G4: $198K | H4: Mike Davis CEO (joined Jul 2024) | I4: Benjamin Lamb CFO (joined May 2025) | J4: Jason Himber Group President, Repair Brands | K4: Felix Gernburd KKR Partner / Board ← PE TARGET | N4: Flag to Charles — KKR intro is Week 1 GPS ask | O4: Week 1 (GPS only) | P4: GPS: THIS IS THE #1 GPS ACTION — Charles → Accel-KKR → KKR → Felix Gernburd. DO NOT approach Neighborly direct. | Q4: Gagan Sinha = CIO (joined Sep 2025). ST renewal window 2025–2027. PE play only. | R4: Neighborly Reunion · Oct 2025 held Nashville — next ~Oct 2026 Nashville. DO NOT attend without PE intro. | S4: ✅ Yes — vendor partners attend | T4: ProTradeNet preferred insurance broker (confirmed — ~170 vendors incl. insurance brokers). Validate specific broker via FDD. | U4: 🟡 Medium — ProTradeNet broker is warm intro path to COO/CFO. PE intro only. | V4: SOURCE: Mr. Rooter FDD (franchiseba.com 2025) / Aire Serv FDD 2025 / ProTradeNet confirmed via neighborlybrands.com ITEM 11 — Technology: ServiceTitan explicitly named as required software system across all core brands. On ST since 2012 (Mr. Handyman, Aire Serv, Mr. Rooter, Mr. Electric per ServiceTitan press release). ITEM 8 — Vendors: ProTradeNet ~170 preferred vendors including insurance brokers. Specific broker named in brand-level FDDs. Broker = warm intro path to COO/CFO. ITEM 19 — Aire Serv 2025: 158 reporting businesses, 1/1/24-12/31/24 per FDD. Full financials behind paywall. ⚠️ DO NOT APPROACH DIRECT. PE intro only via Charles → KKR → Felix Gernburd. ST RENEWAL WINDOW: 2025-2027. Only leverage is PE relationship. | W4: 📊 USE INSIGHT ENGINE → ROI Calculator tab ⚠️ DO NOT RUN INSIGHT ENGINE until PE intro confirmed. IF/WHEN PE intro secured, pre-populate: • Technicians: 13,259 • Avg Jobs/Tech/Day: 5 (mature ST-optimized system) • Avg Revenue/Job: $400 • Focus: ST renewal window — Telematics angle via GPS Insight Conversation is about GPS Insight telematics (Smart Fleet USA contract renewal), not ServiceBridge FSM displacement. 3-Way Scenario: KKR exit at 10-12x multiple. | X4: 76.5 🔴 PE-GATED — DO NOT APPROACH DIRECT | Y4: Charles Layne → Accel-KKR → KKR → Felix Gernburd ⚠️ DO NOT approach direct under any circumstances GPS Insight #1 priority action — Charles follow-up TODAY | Z4: 4/20 20 (limited; ST mandate caps) | AA4: 14/15 90 (13,259 techs — largest in P1) | AB4: 13/15 85 (KKR — active investor, exit-driven) | AC4: 13/15 85 (Charles Layne → Accel-KKR → KKR warm path) | AD4: 15/15 95 (highest — ST renewals 2025-2027 + KKR window) | AE4: 5/10 50 (ST partial mandate, displaceable on non-ST brands) | AF4: 8/10 80 (consumer-led mix)
A5: 2 | B5: AUTHORITY BRANDS | C5: Apax Partners + BCI | D5: P1 #2 · DISPLACEMENT-READY | E5: 12 | F5: 12098 | G5: $181K | H5: Jay Caiafa CEO (joined Aug 2025) Prev: COO Americas, IHG Hotels 4,600 hotels, 26 countries Data/AI focus — new leadership Rob Weddle — OUT (was CEO) | I5: Josh (last name TBD) CFO (joined Sep 2025) Prev: CFO Primrose Schools Prev: VP Strategy, Cracker Barrel Prev: Home Depot finance | J5: Steve Clemente President & COO, Trades | K5: Tij Bedi CTO (joined Aug 2024) ← PRIMARY entry point Tech/FSM mandate angle 9 non-ST brands greenfield Note: Jay Caiafa (CEO) has data + AI background — lead with operational efficiency | N5: Map 9 non-ST brands + Tij Bedi research | O5: Week 1 (research) | P5: GPS: Apax Partners → Charles Layne for PE intro. Tij Bedi is primary tech champion. | Q5: 9 of 12 brands have no ServiceTitan. No displacement. Ryan Bowes = Chief Dev Officer. | R5: Annual Convention — research needed | S5: Unknown | T5: National program likely via Apax Partners — validate FDD Item 8/11 | U5: 🟡 Medium — $2B+ revenue, institutional program almost certain. Tij Bedi (CTO) not the right contact here. | V5: SOURCE: ServiceTitan press release Sep 2024 / public FDD summaries ITEM 11 — Technology: ServiceTitan named as required platform for 3 brands (Benjamin Franklin, Mister Sparky, One Hour) — announced Sep 2024, transition in 2025. 9 remaining brands have NO FSM mandate. PRIOR PLATFORM: Successware (acquired by Authority Brands 2019) — being replaced by ServiceTitan. ✅ GREENFIELD: ASP, Cleaning Authority, DRYmedic, Junkluggers, Lawn Squad, Monster Tree, Mosquito Squad, Screenmobile, STOP Restoration — 9 brands, no mandate. PRIMARY CONTACT: Tij Bedi (CTO, joined Aug 2024) building tech infrastructure. | W5: 📊 USE INSIGHT ENGINE → ROI Calculator tab PRE-POPULATE WITH (9 non-ST greenfield brands only): • Technicians: ~5,000 (9 non-ST brands est.) • Avg Jobs/Tech/Day: 4 • Avg Revenue/Job: $350 • Working Days: 260 PRIMARY AUDIENCE: Tij Bedi (CTO) — use Competitive Matrix tab to show ServiceBridge vs ServiceTitan side by side. Key message: ServiceBridge for the 9 brands ST doesn't serve. No displacement of existing ST mandate. | X5: 68.5 🟡 ACTIVE | Y5: Charles Layne → Apax Partners PE intro path Tij Bedi (CTO Authority Brands) — new hire Aug 2024, direct LinkedIn Andrea Rowan for brand-level account data | Z5: 12/20 60 (mixed — 3 brands ST mandated, 12 brands open) | AA5: 13/15 85 (12,098 techs) | AB5: 12/15 80 (Apax — active investor + co-investor BCI) | AC5: 11/15 70 (Tij Bedi CTO direct, plus parent path) | AD5: 13/15 85 (Jay Caiafa CEO Aug 2025, Josh Greear CFO Sept 2025 — fresh tech direction) | AE5: 7/10 70 (ServiceTitan partial — 12 non-ST brands displaceable) | AF5: 7/10 70 (mix B2B + consumer)
A6: 3 | B6: EMPOWER BRANDS | C6: MidOcean Partners | D6: P1 #3 · GREENFIELD-LED | E6: 10 | F6: 5150 | G6: $77K | H6: Scott Zide CEO | I6: Michael Borreca SVP & CFO | J6: Tom (last name TBD) COO ⚠️ Verify | K6: R. Scott Sutton Chief Dev Officer | N6: JAN-PRO brand wedge + CEO outreach | O6: Week 1 | P6: GPS: MidOcean → Charles Layne for PE intro before approaching Scott Zide | Q6: Gary Bauer (JAN-PRO Brand President) is brand-level wedge. EBITDA before exit window. | R6: Ignite · Feb 10–12 (just held — next ~Feb 2027, Orlando) | S6: ✅ Yes — 85 vendors attended | T6: Preferred broker via MidOcean PE (likely) — validate FDD Item 8/11 | U6: 🟡 Medium — CFO Michael Borreca owns this. MidOcean institutional. | V6: SOURCE: FDD Exchange 2025 / franchiseba.com / assettfranchise.com JAN-PRO ITEM 8 — Technology: Proprietary software mandated. Technology fee: up to $60/month per franchisee. JAN-PRO ITEM 19: 11,265 unit franchises. Regional developer investment $130K-$421.5K. ⚠️ CONFLICT FLAG: JAN-PRO has proprietary FSM with fee already built in. Confirm gap vs ServiceBridge before outreach on JAN-PRO specifically. ✅ GREENFIELD: 9 non-JAN-PRO brands (Archadeck, Bumble, Canopy, Conserva, FRSTeam, Koala, OLP, Superior Fence, Wallaby) — no FSM named in FDD. These are the entry point with Scott Zide. | W6: 📊 USE INSIGHT ENGINE → ROI Calculator tab PRE-POPULATE WITH (9 non-JAN-PRO greenfield brands): • Technicians: ~3,500 (excl. JAN-PRO) • Avg Jobs/Tech/Day: 3.5 • Avg Revenue/Job: $350 • Working Days: 260 ⚠️ EXCLUDE JAN-PRO from model — proprietary FSM conflict. Run separate scenario for the 9 greenfield brands only. MidOcean exit window framing: EBITDA uplift × 8x multiple = enterprise value story for Scott Zide + Michael Borreca. | X6: 66.2 🟡 ACTIVE | Y6: Charles Layne (CEO) — MidOcean Partners PE intro path Andrea Rowan (GM) — account detail ⚠️ JAN-PRO conflict — approach via 9 greenfield brands only | Z6: 18/20 90 (highest — ServiceMinder partial, most brands open) | AA6: 8/15 55 (5,150 techs — mid-tier) | AB6: 12/15 80 (MidOcean Year 3-4, building toward exit) | AC6: 12/15 80 (Scott Zide CEO + Gary Bauer JAN-PRO brand wedge) | AD6: 9/15 60 (mid-term, not immediate) | AE6: 3/10 30 (ServiceMinder 2-4x partial) | AF6: 4/10 40 (Commercial 70%+ — weaker consumer fit)
A7: 4 | B7: RESIBRANDS | C7: Angel / Codie Sanchez | D7: P1 #4 · FAST-CYCLE | E7: 5 | F7: 2550 | G7: $38K | H7: Steven Montgomery Founder & CEO | I7: (None confirmed) Lean team | J7: Allan (last name TBD) Co-Founder ⚠️ Verify | K7: Steven Montgomery (handles directly) | N7: Direct LinkedIn to Steven Montgomery | O7: Week 2 | Q7: Founder-backed. No PE committee. One conversation closes this. $1.67/tech/day message. | R7: No confirmed annual event (emerging brand) | S7: Unknown | T7: Franchisees self-direct — lean founder operation, no group program likely | U7: 🟢 Low | V7: SOURCE: Public company info / IFA 2026 ITEM 11 — Technology: ResiConnect handles inbound scheduling only. No full FSM disclosed in any publicly available FDD summary. ITEM 19 — Unit Economics: FDD not publicly analyzed. Angel/founder-backed — lean disclosure likely. APPROACH: Steven Montgomery directly accessible. No FDD deep-dive needed before first conversation. | W7: 📊 USE INSIGHT ENGINE → ROI Calculator tab PRE-POPULATE WITH: • Technicians: 2,550 • Avg Jobs/Tech/Day: 5 (painting model — volume-based) • Avg Revenue/Job: $200 • Working Days: 260 FOUNDER PITCH: $1.67/tech/day message. Run Insight Engine conservative scenario only — Steven Montgomery responds to simplicity, not PE math. Total: 2,550 techs × $1.67/day × 260 days = ~$1.1M annual value | X7: 60.2 🟢 ACTIVE | Y7: No current GPS Insight relationship Steven Montgomery accessible directly — call scheduled Apr 15 Direct founder path — no GPS intro needed | Z7: 17/20 85 (ResiConnect = scheduling only, paper for ops) | AA7: 7/15 45 (2,550 techs — smallest) | AB7: 6/15 40 (Angel/founder, no PE pressure) | AC7: 14/15 90 (Kevin Luu direct, fast decision velocity) | AD7: 11/15 75 (entrepreneurial — moves fast) | AE7: 7/10 70 (mostly greenfield) | AF7: 8/10 75 (consumer-led)
A8: 5 | B8: FIVE STAR FRANCHISING | C8: Princeton Equity Group | D8: P1 #5 · WEDGE-BRAND | E8: 5 | F8: 2350 | G8: $35K | H8: Scott Abbott CEO & Co-Founder | I8: Steve White CFO | J8: Chad Jones COO & Co-Founder | K8: Michael Moorhouse Brand President, Mosquito Shield | N8: Mosquito Shield brand wedge + CEO outreach | O8: Week 2 | Q8: Princeton Equity Year 5. EBITDA story lands immediately. Greenfield — no incumbent. | R8: Home Services Summit (HSS) · Jan 14–17 (just held — next ~Jan 2027, Las Vegas) | S8: ✅ Yes — vendor partners attend | T8: Preferred broker likely via Princeton Equity — validate FDD | U8: 🟡 Medium — Year 5 PE. CFO Steve White owns. | V8: SOURCE: Public FDD summaries — full FDD not yet pulled ITEM 11 — Technology: ProNexis named as 24/7 sales support system. No FSM platform mandated in publicly available analysis. ACTION: Pull California or Wisconsin FDD for Items 8 and 11 before scripting. KNOWN: Princeton Equity Year 5. CFO Steve White owns the numbers conversation. | W8: 📊 USE INSIGHT ENGINE → ROI Calculator tab PRE-POPULATE WITH: • Technicians: 2,350 • Avg Jobs/Tech/Day: 4 • Avg Revenue/Job: $300 • Working Days: 260 Princeton Equity Year 5 → exit window framing. Run 3-Way Scenario with 8x multiple for Steve White (CFO). Mosquito Shield wedge: seasonal route model, strong FSM fit. FieldRoutes conflict risk — verify Mosquito Shield before model. | X8: 59.2 🟡 ACTIVE | Y8: No current GPS Insight relationship Princeton Equity → Charles Layne path for PE intro Scott Abbott direct on LinkedIn — Five Star CEO accessible | Z8: 14/20 70 (mixed — FieldRoutes possible at Mosquito Shield) | AA8: 7/15 45 (2,350 techs) | AB8: 9/15 60 (Princeton Equity) | AC8: 11/15 75 (Mosquito Shield wedge to Five Star CEO Scott Abbott) | AD8: 9/15 60 (mid-term) | AE8: 5/10 50 (FieldRoutes possible) | AF8: 7/10 70 (consumer-led)
A9: 6 | B9: PREMIUM SERVICE BRANDS | C9: Susquehanna Private Capital | D9: P1 #6 · GREENFIELD-OPEN | E9: 8 | F9: 4950 | G9: $74K | H9: Paul Flick Founder & CEO | I9: (TBD) VP Finance ⚠️ Research | J9: Roxanne Conrad COO | K9: Gabe Colon EVP Performance | N9: RooterMan brand president outreach | O9: Week 2 | Q9: RooterMan brand president (name TBD) is 300-loc plumbing wedge into PSB portfolio. | R9: Annual Convention — research needed | S9: Unknown | T9: Validate via FDD Item 8/11 — Susquehanna PE backed | U9: 🟡 Medium — validate before outreach | V9: SOURCE: State registries — FDD not yet pulled ACTION: Pull Wisconsin or California FDD for Items 8, 11, 19 before outreach. KNOWN: RooterMan = 300 plumbing locations. PSB backed by Susquehanna Private Capital. | W9: 📊 USE INSIGHT ENGINE → ROI Calculator tab PRE-POPULATE WITH: • Technicians: 4,950 • Avg Jobs/Tech/Day: 4 • Avg Revenue/Job: $300 (painting/cleaning/plumbing mix) • Working Days: 260 RooterMan wedge: 300 locations, plumbing dispatch. Run Insight Engine at brand level first (RooterMan) → then scale to full PSB network for CFO conversation. | X9: 59.0 🟡 ACTIVE | Y9: Andrea Rowan (GM, ServiceBridge) — day-to-day contact Verify GPS Insight telematics customers in PSB network via Andrea Paul Flick direct path — no PE intro needed | Z9: 17/20 85 (RooterMan dominates — paper-based) | AA9: 8/15 50 (4,950 techs) | AB9: 6/15 40 (Susquehanna — less active) | AC9: 9/15 60 (Paul Flick CEO — verify warm path) | AD9: 8/15 50 (mid-term) | AE9: 7/10 70 (mostly greenfield) | AF9: 7/10 70 (consumer-led)
A10: 7 | B10: HOMEFRONT BRANDS | C10: Dudan Group (Family Office) | D10: P1 #7 · MONITOR-MODE | E10: 5 | F10: 2550 | G10: $38K | H10: Jeff Dudan Chairman & CEO | I10: Mike Dudan CFO | J10: Michael O'Driscoll COO & President of Franchising | K10: Zack Dudan Chief Growth Officer | N10: CEO direct outreach + Window Hero brand wedge | O10: Week 2 | Q10: Jeff Dudan is a podcaster + Forbes contributor — accessible. Tyler Kirk (Window Hero) is wedge. | R10: Homecoming (4th annual) · ~Nov 2026, Orlando — STILL TIME TO GET IN | S10: ✅ Yes — vendor partners attend | T10: Likely individual franchisee insurance — young company, no group program confirmed | U10: 🟢 Low — Jeff Dudan family office, not institutional PE | V10: SOURCE: Public company info / franchisewire.com ITEM 11 — Technology: No FSM platform disclosed in any public FDD analysis. Homecoming 3 (Nov 2025) featured digital marketing speaker — no FSM announced. NOTE: Franchisee satisfaction issues flagged Dec 2025 (Unhappy Franchisee post). Verify system health before vendor commitment. APPROACH: Jeff Dudan directly via podcast/Forbes channel first. | W10: 📊 USE INSIGHT ENGINE → ROI Calculator tab PRE-POPULATE WITH: • Technicians: 2,550 • Avg Jobs/Tech/Day: 3 • Avg Revenue/Job: $400 (fence/exterior) • Working Days: 260 Jeff Dudan is founder-operated — run conservative scenario only. Focus on per-franchisee story, not PE exit math. ⚠️ Note franchisee satisfaction issues — position ServiceBridge as proof point for system health, not just efficiency. | X10: 44.0 ⚪ MONITOR | Y10: No current GPS Insight relationship Jeff Dudan — founder, podcaster, Forbes contributor — direct approach Homecoming 4 vendor path = Zack Dudan (CGO) | Z10: 16/20 80 (newer brands — paper-based) | AA10: 5/15 35 (2,550 techs — smaller) | AB10: 3/15 20 (Family office, no exit pressure) | AC10: 8/15 50 (Tyler Kirk Window Hero, Jeff/Zack Dudan corp) | AD10: 5/15 30 (Q3/Q4 2026 reassessment) | AE10: 6/10 60 (mostly greenfield) | AF10: 7/10 70 (consumer)
B11: ═══ P2 FRANCHISORS · EXISTING FOOTPRINT ═══
A12: P2-1 | B12: BELFOR | C12: American Securities | D12: P2 · DE-FACTO ANCHOR | E12: 14 | F12: 9250 | G12: $260K+ | H12: Rusty Amarante, CR President, BFG | I12: Sheldon Yellen CEO, Holdings | J12: Dan Tarantin COO, BFG | K12: Doug Smith SVP Franchise Dev Beth Toenies VP Franchise Dev | N12: Deep profile + contact map | O12: Week 1 | P12: GPS: American Securities → Charles Layne → PE warm intro before outreach to Sheldon Yellen | Q12: ═ P2 · DE-FACTO ANCHOR ═ Year 6 hold — American Securities exit window 2026-2027. HOODZ + DUCTZ at 94% SB de facto. Convert de facto into mandate before exit. | Zero FSM mandate. 30 new territories Dec 2024. Start here. | R12: BELFOR Annual Conference · March (just held — next ~Mar 2027) | S12: Unknown | T12: Insurance carriers ARE the revenue channel for restoration brands. Claims Partnership Program launched Oct 2024. Carriers: Travelers, Allstate, State Farm, USAA. | U12: 🔴 HIGH — Carriers dispatch restoration brands. ServiceBridge job documentation = defensible claims record. Reframe pitch to Rusty as carrier relationship tool, not FSM. | V12: SOURCE: Publicly available FDD analysis (2024 FDD) + franchiseba.com ITEM 11 — Technology: 'Proprietary business management and job tracking tools' named. No third-party FSM disclosed. GREENFIELD confirmed. ITEM 19 — Unit Economics (2023 data, 94 franchisees, 157 locations): • Avg gross sales per location: ~$480K • Top 25% avg: $1,654,321 • Est. EBITDA at 15% margin: ~$72K/location • Avg invoice per job: ~$4,500 • Insurance carriers refer ~40% of jobs ROYALTY: 10% on first $499K → 7% above $2M + 2% Marketing Fund SERVICEBRIDGE EBITDA CASE: 5-pt margin improvement = $24K addl EBITDA/location. Across 178 locations = $4.3M system-wide EBITDA creation. | W12: 📊 USE INSIGHT ENGINE → ROI Calculator tab PRE-POPULATE WITH: • Technicians: 9,250 (network) | Per brand: see below • Avg Jobs/Tech/Day: 3 (restoration = emergency dispatch, lower frequency) • Avg Revenue/Job: $4,500 (FDD-sourced: avg 1-800 WD invoice 2024) • Working Days: 260 • Avg Tech Wage: $28/hr FSM UPLIFT (conservative for greenfield): • Additional Jobs: 0.3/tech/day • Admin Saved: 1.0 hr/tech/day • Invoice Cycle Reduction: 5 days (critical for insurance payment lag) TELEMATICS (GPS Insight warm flag): • Fuel Savings: $1,800/vehicle/yr • Insurance Reduction: 8% 3-WAY SCENARIO OUTPUTS (base case, 1-800 WD 178 locations): • FDD Item 19: $480K avg/location • 5-pt margin improvement = $24K EBITDA/location • 178 locations × $24K = $4.3M system EBITDA creation • At 8x exit multiple = $34.4M enterprise value uplift ⚠️ USE THE TOP-25% NUMBER ($1.65M) for STRETCH scenario with Rusty | X12: P2 SET 🟡 EXISTING FOOTPRINT | Y12: Charles Layne (CEO, GPS Insight) — Personal friend + primary exec relationship American Securities → Accel-KKR → KKR intro chain Charles owns the PE intro. Mike owns the direct franchisee path. | Z12: 25/25 Greenfield — no FSM mandate found | AA12: 15/20 9,250 techs — large network | AB12: 15/20 American Securities — active PE, EBITDA expansion thesis | AC12: 15/15 Full FDD analysis loaded — unit economics confirmed | AD12: 10/10 Charles Layne direct — highest access level | AE12: 5/5 GPS Insight relationship confirmed | AF12: 5/5 14 brands — multiple pilot targets within network
A13: P2-2 | B13: EVIVE BRANDS | C13: The Riverside Company ($13B+ AUM) | D13: P2 · GROWING ANCHOR | E13: 7 | F13: 1100 | G13: $30K-50K (estimated) | H13: Ryan Parsons CEO, Evive Brands Known-friendly to Mike — warm path | I13: TBD — research | J13: TBD — research | K13: TBD — research | L13: P2 — RESEARCH | N13: Profile + Brothers Gutters anchor leverage | P13: GPS: Riverside PE → Charles Layne. Andrea direct on Brothers Gutters. | Q13: ═ P2 · GROWING ANCHOR ═ Year 3 hold — Riverside-owned (formed 2023). Brothers Gutters at 43% SB under new contract. Maid Brigade (2024 acquisition) greenfield within Evive. Ryan Parsons = warmest P2 relationship. Same parent as Threshold (Riverside) — coordinate engagement. | X13: P2 SET 🟢 EXISTING FOOTPRINT — GROWING
A14: P2-3 | B14: THRESHOLD BRANDS | C14: Riverside Company | D14: P2 · AT-RISK ANCHOR | E14: 10 | F14: 6250 | G14: $94K | H14: Hagan Kappler CEO ⚠️ VERIFY | I14: Scott Fink / Brandon Brown CFO ⚠️ VERIFY | J14: Andrea Hohermuth COO | K14: Scott Sutton Chief Growth Officer | N14: Profile + contacts map | O14: Week 1 | P14: GPS: Riverside PE → Charles Layne. ⚠️ Verify Hagan Kappler still CEO (Daisy link 2025) | Q14: ═ P2 · AT-RISK ANCHOR ═ Year 6+ hold — Riverside-owned. USA Insulation transitioning OFF SB (75% → 0% over next year). Ted DeMarino CEO + Billy Newby CFO new. Defensive posture: defend if reversible, reset relationship at brand-corp level. Same parent as Evive. | Promised franchisees proprietary software — undelivered. ServiceBridge closes that gap. | R14: Annual Convention · Date/location TBD — research needed | S14: Unknown | T14: Preferred broker via Riverside PE (likely) — validate FDD Item 8/11 | U14: 🟡 Medium — PE-backed with structured program. CFO contact. | V14: SOURCE: Public FDD summaries / state registries ITEM 11 — Technology: Promised 'proprietary technology' to franchisees — undelivered per franchisee feedback (Glassdoor, FDD analysis). ITEM 19 — Unit Economics: Not publicly detailed in FDD analysis. Validate via Wisconsin/California FDD registry. KEY ANGLE: Unfulfilled tech promise = ServiceBridge delivers what Threshold told franchisees they'd get. | W14: 📊 USE INSIGHT ENGINE → ROI Calculator tab PRE-POPULATE WITH: • Technicians: 6,250 (network total) • Avg Jobs/Tech/Day: 4 • Avg Revenue/Job: $250 (cleaning/pest model) • Working Days: 260 KEY ANGLE FOR THRESHOLD: Unfulfilled tech promise = franchisees already expect this. Position ServiceBridge as delivering what Threshold promised. Run 3-Way Scenario showing EBITDA uplift before Riverside PE exit. | X14: P2 SET 🔴 EXISTING FOOTPRINT — AT-RISK | Y14: Charles Layne (CEO) — Riverside Company PE intro path Andrea Rowan (GM) — account detail + telematics customer list Verify Hagan Kappler CEO status before outreach | Z14: 10/25 FSM status unconfirmed — action needed | AA14: 15/20 6,250 techs — large network | AB14: 18/20 Riverside Company — Year 4, approaching exit window | AC14: 15/15 Full FDD analysis loaded — unit economics confirmed | AD14: 10/10 Charles Layne direct — highest access level | AE14: 5/5 GPS Insight relationship confirmed | AF14: 5/5 10 brands — multiple pilot targets within network

Sheet Track 2 · Franchisees
A1: 85 PRIORITY FRANCHISEE BRANDS · Track 2 · Greenfield Volume Pipeline
A2: Velocity GTM Co LLC · Sorted by parent franchisor · GPS Insight warm accounts prioritized · v15.6 — validated April 29, 2026
A3: # | B3: BRAND / FRANCHISEE | C3: PARENT FRANCHISOR | D3: TRADE | E3: LOCATIONS | F3: TECHS (EST.) | G3: FSM STATUS | H3: GPS WARM? | I3: PILOT POTENTIAL | J3: CURRENT FSM PLATFORM | K3: CONFLICT RISK | L3: TELEMATICS PROVIDER | M3: GPS INSIGHT CUSTOMER? ← Andrea to Verify | N3: INSURANCE PROGRAM / CARRIER | O3: INSURANCE GTM ANGLE | P3: PRIMARY CONTACT | Q3: CONTACT TITLE | R3: OWNER / DECISION MAKER | S3: OPS MGR / OFFICE MANAGER | T3: GPS INSIGHT ACCOUNT REP ← Warm intro path | U3: OUTREACH STATUS | V3: LAST CONTACT | W3: NEXT STEP | X3: NEXT DATE | Y3: NOTES | Z3: FDD INTEL (Source + Key Facts) | AA3: INSIGHT ENGINE NOTES ← ROI angle for outreach | AE3: FRANCHISEE SCORE / 100 | AF3: FRANCHISOR BONUS + 0/5/15/25 | AG3: COMBINED SCORE / 125
A4: 1 | B4: Aire Serv | C4: Neighborly | D4: HVAC | E4: 500 | F4: 5 | G4: Partial/ST | H4: TBD | I4: MED | J4: ServiceTitan | K4: 🔴 High | L4: Smart Fleet USA | M4: No — Smart Fleet USA | N4: ProTradeNet preferred broker — validate FDD | O4: 🟡 Medium | P4: (Franchisee Owner) | Q4: Owner/Operator | R4: TBD — franchisee owner ⚠️ DO NOT approach — Neighborly PE intro required first KKR → Charles Layne → Felix Gernburd — PE intro only | S4: TBD — office manager Smart Fleet USA telematics (NOT GPS Insight) | T4: Smart Fleet USA (NOT GPS Insight) ⚠️ No warm GPS Insight intro path Do not approach without PE intro confirmed | W4: Profile + conflict check | Y4: ServiceTitan incumbent — check mandate status before outreach | Z4: SOURCE: Aire Serv FDD 2025 / franchise.neighborly.com ITEM 11: ServiceTitan REQUIRED — 'our Software System' referenced in Item 19. ITEM 19 (2024 data): 158 reporting businesses, 1/1/24-12/31/24 full year. Avg gross sales: not disclosed in public summary — pull FDD. Telematics: Smart Fleet USA confirmed. CONFLICT: High on FSM. | AA4: ⚠️ ST mandated — no FSM pitch. Telematics only if GPS Insight customer confirmed. Do not run Insight Engine until PE intro secured. | AE4: 36 | AF4: +5 | AG4: 41 ⚪ HOLD
A5: 2 | B5: Glass Doctor | C5: Neighborly | D5: Auto/Home Glass | E5: 500 | F5: 3 | G5: Partial/ST | H5: TBD | I5: LOW | J5: ServiceTitan | K5: 🔴 High | L5: Smart Fleet USA | M5: No — Smart Fleet USA | N5: ProTradeNet preferred broker — validate FDD | O5: 🟡 Medium | P5: (Franchisee Owner) | Q5: Owner/Operator | R5: TBD — franchisee owner ⚠️ DO NOT approach — Neighborly PE intro required first KKR → Charles Layne → Felix Gernburd — PE intro only | S5: TBD — office manager Smart Fleet USA telematics (NOT GPS Insight) | T5: Smart Fleet USA (NOT GPS Insight) ⚠️ No warm GPS Insight intro path Do not approach without PE intro confirmed | W5: Profile + conflict check | Y5: ST mandate — check renewal window | Z5: Pull from Wisconsin/California FDD registry. Neighborly brand — verify ST mandate status first. | AA5: ⚠️ ST mandated — no FSM pitch. Telematics only if GPS Insight customer confirmed. Do not run Insight Engine until PE intro secured. | AE5: 19 | AF5: +5 | AG5: 24 ⚪ HOLD
A6: 3 | B6: Lawn Pride | C6: Neighborly | D6: Lawn Care | E6: 150 | F6: 3 | G6: Partial/ST | H6: TBD | I6: MED | J6: FieldRoutes (ST) | K6: 🔴 High | L6: Smart Fleet USA | M6: No — Smart Fleet USA | N6: Validate via FDD | O6: ❓ Unknown | P6: (Franchisee Owner) | Q6: Owner/Operator | R6: TBD — franchisee owner ⚠️ DO NOT approach — Neighborly PE intro required first KKR → Charles Layne → Felix Gernburd — PE intro only | S6: TBD — office manager Smart Fleet USA telematics (NOT GPS Insight) | T6: Smart Fleet USA (NOT GPS Insight) ⚠️ No warm GPS Insight intro path Do not approach without PE intro confirmed | W6: Profile + conflict check | Y6: Route model — check ST mandate status | Z6: Pull from Wisconsin/California FDD registry. Neighborly brand — verify ST mandate status first. | AA6: ⚠️ ST mandated — no FSM pitch. Telematics only if GPS Insight customer confirmed. Do not run Insight Engine until PE intro secured. | AE6: 24 | AF6: +5 | AG6: 29 ⚪ HOLD
A7: 4 | B7: Molly Maid | C7: Neighborly | D7: Cleaning | E7: 448 | F7: 3 | G7: Partial/ST | H7: TBD | I7: MED | J7: ServiceTitan | K7: 🔴 High | L7: Smart Fleet USA | M7: No — Smart Fleet USA | N7: Validate via FDD | O7: ❓ Unknown | P7: (Franchisee Owner) | Q7: Owner/Operator | R7: TBD — franchisee owner ⚠️ DO NOT approach — Neighborly PE intro required first KKR → Charles Layne → Felix Gernburd — PE intro only | S7: TBD — office manager Smart Fleet USA telematics (NOT GPS Insight) | T7: Smart Fleet USA (NOT GPS Insight) ⚠️ No warm GPS Insight intro path Do not approach without PE intro confirmed | W7: Profile + conflict check | Y7: Recurring cleaning crews | Z7: Pull from Wisconsin/California FDD registry. Neighborly brand — verify ST mandate status first. | AA7: ⚠️ ST mandated — no FSM pitch. Telematics only if GPS Insight customer confirmed. Do not run Insight Engine until PE intro secured. | AE7: 21 | AF7: +5 | AG7: 26 ⚪ HOLD
